2023-04-28 19:30:23,431 - telegram.ext._application - INFO - Application started
2023-04-28 19:31:02,352 - telegram.ext._application - ERROR - No error handlers are registered, logging exception.
Traceback (most recent call last):
  File "C:\Users\matve\Desktop\tg_bot_project\venv\lib\site-packages\sqlalchemy\engine\base.py", line 1964, in _exec_single_context
    self.dialect.do_execute(
  File "C:\Users\matve\Desktop\tg_bot_project\venv\lib\site-packages\sqlalchemy\engine\default.py", line 748, in do_execute
    cursor.execute(statement, parameters)
sqlite3.IntegrityError: UNIQUE constraint failed: big_data.user_id

The above exception was the direct cause of the following exception:

Traceback (most recent call last):
  File "C:\Users\matve\Desktop\tg_bot_project\venv\lib\site-packages\telegram\ext\_application.py", line 1115, in process_update
    await coroutine
  File "C:\Users\matve\Desktop\tg_bot_project\venv\lib\site-packages\telegram\ext\_conversationhandler.py", line 826, in handle_update
    new_state: object = await handler.handle_update(
  File "C:\Users\matve\Desktop\tg_bot_project\venv\lib\site-packages\telegram\ext\_handler.py", line 141, in handle_update
    return await self.callback(update, context)
  File "C:\Users\matve\Desktop\tg_bot_project\output\app.py", line 111, in send_stt_msg_dialog
    total_msg_func(update, msg_format="voice")
  File "C:\Users\matve\Desktop\tg_bot_project\output\funcs_backend.py", line 213, in total_msg_func
    db_sess.commit()
  File "C:\Users\matve\Desktop\tg_bot_project\venv\lib\site-packages\sqlalchemy\orm\session.py", line 1903, in commit
    trans.commit(_to_root=True)
  File "<string>", line 2, in commit
  File "C:\Users\matve\Desktop\tg_bot_project\venv\lib\site-packages\sqlalchemy\orm\state_changes.py", line 137, in _go
    ret_value = fn(self, *arg, **kw)
  File "C:\Users\matve\Desktop\tg_bot_project\venv\lib\site-packages\sqlalchemy\orm\session.py", line 1218, in commit
    self._prepare_impl()
  File "<string>", line 2, in _prepare_impl
  File "C:\Users\matve\Desktop\tg_bot_project\venv\lib\site-packages\sqlalchemy\orm\state_changes.py", line 137, in _go
    ret_value = fn(self, *arg, **kw)
  File "C:\Users\matve\Desktop\tg_bot_project\venv\lib\site-packages\sqlalchemy\orm\session.py", line 1193, in _prepare_impl
    self.session.flush()
  File "C:\Users\matve\Desktop\tg_bot_project\venv\lib\site-packages\sqlalchemy\orm\session.py", line 4155, in flush
    self._flush(objects)
  File "C:\Users\matve\Desktop\tg_bot_project\venv\lib\site-packages\sqlalchemy\orm\session.py", line 4292, in _flush
    transaction.rollback(_capture_exception=True)
  File "C:\Users\matve\Desktop\tg_bot_project\venv\lib\site-packages\sqlalchemy\util\langhelpers.py", line 147, in __exit__
    raise exc_value.with_traceback(exc_tb)
  File "C:\Users\matve\Desktop\tg_bot_project\venv\lib\site-packages\sqlalchemy\orm\session.py", line 4252, in _flush
    flush_context.execute()
  File "C:\Users\matve\Desktop\tg_bot_project\venv\lib\site-packages\sqlalchemy\orm\unitofwork.py", line 467, in execute
    rec.execute(self)
  File "C:\Users\matve\Desktop\tg_bot_project\venv\lib\site-packages\sqlalchemy\orm\unitofwork.py", line 644, in execute
    util.preloaded.orm_persistence.save_obj(
  File "C:\Users\matve\Desktop\tg_bot_project\venv\lib\site-packages\sqlalchemy\orm\persistence.py", line 93, in save_obj
    _emit_insert_statements(
  File "C:\Users\matve\Desktop\tg_bot_project\venv\lib\site-packages\sqlalchemy\orm\persistence.py", line 1020, in _emit_insert_statements
    result = connection.execute(
  File "C:\Users\matve\Desktop\tg_bot_project\venv\lib\site-packages\sqlalchemy\engine\base.py", line 1414, in execute
    return meth(
  File "C:\Users\matve\Desktop\tg_bot_project\venv\lib\site-packages\sqlalchemy\sql\elements.py", line 486, in _execute_on_connection
    return connection._execute_clauseelement(
  File "C:\Users\matve\Desktop\tg_bot_project\venv\lib\site-packages\sqlalchemy\engine\base.py", line 1638, in _execute_clauseelement
    ret = self._execute_context(
  File "C:\Users\matve\Desktop\tg_bot_project\venv\lib\site-packages\sqlalchemy\engine\base.py", line 1842, in _execute_context
    return self._exec_single_context(
  File "C:\Users\matve\Desktop\tg_bot_project\venv\lib\site-packages\sqlalchemy\engine\base.py", line 1983, in _exec_single_context
    self._handle_dbapi_exception(
  File "C:\Users\matve\Desktop\tg_bot_project\venv\lib\site-packages\sqlalchemy\engine\base.py", line 2326, in _handle_dbapi_exception
    raise sqlalchemy_exception.with_traceback(exc_info[2]) from e
  File "C:\Users\matve\Desktop\tg_bot_project\venv\lib\site-packages\sqlalchemy\engine\base.py", line 1964, in _exec_single_context
    self.dialect.do_execute(
  File "C:\Users\matve\Desktop\tg_bot_project\venv\lib\site-packages\sqlalchemy\engine\default.py", line 748, in do_execute
    cursor.execute(statement, parameters)
sqlalchemy.exc.IntegrityError: (sqlite3.IntegrityError) UNIQUE constraint failed: big_data.user_id
[SQL: INSERT INTO big_data (user_id, start_date) VALUES (?, ?)]
[parameters: (871689175, '2023-04-28 19:31:02.347745')]
(Background on this error at: https://sqlalche.me/e/20/gkpj)
2023-04-28 19:31:37,982 - telegram.ext._application - INFO - Application is stopping. This might take a moment.
2023-04-28 19:31:37,982 - telegram.ext._application - INFO - Application.stop() complete
2023-04-28 19:32:16,148 - telegram.ext._application - INFO - Application started
2023-04-28 19:32:31,166 - telegram.ext._updater - ERROR - Error while getting Updates: Conflict: terminated by other getUpdates request; make sure that only one bot instance is running
2023-04-28 19:32:31,166 - telegram.ext._application - ERROR - No error handlers are registered, logging exception.
Traceback (most recent call last):
  File "C:\Users\matve\Desktop\tg_bot_project\venv\lib\site-packages\telegram\ext\_updater.py", line 607, in _network_loop_retry
    if not await action_cb():
  File "C:\Users\matve\Desktop\tg_bot_project\venv\lib\site-packages\telegram\ext\_updater.py", line 335, in polling_action_cb
    raise exc
  File "C:\Users\matve\Desktop\tg_bot_project\venv\lib\site-packages\telegram\ext\_updater.py", line 320, in polling_action_cb
    updates = await self.bot.get_updates(
  File "C:\Users\matve\Desktop\tg_bot_project\venv\lib\site-packages\telegram\ext\_extbot.py", line 530, in get_updates
    updates = await super().get_updates(
  File "C:\Users\matve\Desktop\tg_bot_project\venv\lib\site-packages\telegram\_bot.py", line 368, in decorator
    result = await func(*args, **kwargs)  # skipcq: PYL-E1102
  File "C:\Users\matve\Desktop\tg_bot_project\venv\lib\site-packages\telegram\_bot.py", line 3623, in get_updates
    await self._post(
  File "C:\Users\matve\Desktop\tg_bot_project\venv\lib\site-packages\telegram\_bot.py", line 456, in _post
    return await self._do_post(
  File "C:\Users\matve\Desktop\tg_bot_project\venv\lib\site-packages\telegram\ext\_extbot.py", line 312, in _do_post
    return await super()._do_post(
  File "C:\Users\matve\Desktop\tg_bot_project\venv\lib\site-packages\telegram\_bot.py", line 487, in _do_post
    return await request.post(
  File "C:\Users\matve\Desktop\tg_bot_project\venv\lib\site-packages\telegram\request\_baserequest.py", line 165, in post
    result = await self._request_wrapper(
  File "C:\Users\matve\Desktop\tg_bot_project\venv\lib\site-packages\telegram\request\_baserequest.py", line 330, in _request_wrapper
    raise Conflict(message)
telegram.error.Conflict: Conflict: terminated by other getUpdates request; make sure that only one bot instance is running
2023-04-28 19:32:36,322 - telegram.ext._updater - ERROR - Error while getting Updates: Conflict: terminated by other getUpdates request; make sure that only one bot instance is running
2023-04-28 19:32:36,322 - telegram.ext._application - ERROR - No error handlers are registered, logging exception.
Traceback (most recent call last):
  File "C:\Users\matve\Desktop\tg_bot_project\venv\lib\site-packages\telegram\ext\_updater.py", line 607, in _network_loop_retry
    if not await action_cb():
  File "C:\Users\matve\Desktop\tg_bot_project\venv\lib\site-packages\telegram\ext\_updater.py", line 335, in polling_action_cb
    raise exc
  File "C:\Users\matve\Desktop\tg_bot_project\venv\lib\site-packages\telegram\ext\_updater.py", line 320, in polling_action_cb
    updates = await self.bot.get_updates(
  File "C:\Users\matve\Desktop\tg_bot_project\venv\lib\site-packages\telegram\ext\_extbot.py", line 530, in get_updates
    updates = await super().get_updates(
  File "C:\Users\matve\Desktop\tg_bot_project\venv\lib\site-packages\telegram\_bot.py", line 368, in decorator
    result = await func(*args, **kwargs)  # skipcq: PYL-E1102
  File "C:\Users\matve\Desktop\tg_bot_project\venv\lib\site-packages\telegram\_bot.py", line 3623, in get_updates
    await self._post(
  File "C:\Users\matve\Desktop\tg_bot_project\venv\lib\site-packages\telegram\_bot.py", line 456, in _post
    return await self._do_post(
  File "C:\Users\matve\Desktop\tg_bot_project\venv\lib\site-packages\telegram\ext\_extbot.py", line 312, in _do_post
    return await super()._do_post(
  File "C:\Users\matve\Desktop\tg_bot_project\venv\lib\site-packages\telegram\_bot.py", line 487, in _do_post
    return await request.post(
  File "C:\Users\matve\Desktop\tg_bot_project\venv\lib\site-packages\telegram\request\_baserequest.py", line 165, in post
    result = await self._request_wrapper(
  File "C:\Users\matve\Desktop\tg_bot_project\venv\lib\site-packages\telegram\request\_baserequest.py", line 330, in _request_wrapper
    raise Conflict(message)
telegram.error.Conflict: Conflict: terminated by other getUpdates request; make sure that only one bot instance is running
2023-04-28 19:32:41,949 - telegram.ext._updater - ERROR - Error while getting Updates: Conflict: terminated by other getUpdates request; make sure that only one bot instance is running
2023-04-28 19:32:41,950 - telegram.ext._application - ERROR - No error handlers are registered, logging exception.
Traceback (most recent call last):
  File "C:\Users\matve\Desktop\tg_bot_project\venv\lib\site-packages\telegram\ext\_updater.py", line 607, in _network_loop_retry
    if not await action_cb():
  File "C:\Users\matve\Desktop\tg_bot_project\venv\lib\site-packages\telegram\ext\_updater.py", line 335, in polling_action_cb
    raise exc
  File "C:\Users\matve\Desktop\tg_bot_project\venv\lib\site-packages\telegram\ext\_updater.py", line 320, in polling_action_cb
    updates = await self.bot.get_updates(
  File "C:\Users\matve\Desktop\tg_bot_project\venv\lib\site-packages\telegram\ext\_extbot.py", line 530, in get_updates
    updates = await super().get_updates(
  File "C:\Users\matve\Desktop\tg_bot_project\venv\lib\site-packages\telegram\_bot.py", line 368, in decorator
    result = await func(*args, **kwargs)  # skipcq: PYL-E1102
  File "C:\Users\matve\Desktop\tg_bot_project\venv\lib\site-packages\telegram\_bot.py", line 3623, in get_updates
    await self._post(
  File "C:\Users\matve\Desktop\tg_bot_project\venv\lib\site-packages\telegram\_bot.py", line 456, in _post
    return await self._do_post(
  File "C:\Users\matve\Desktop\tg_bot_project\venv\lib\site-packages\telegram\ext\_extbot.py", line 312, in _do_post
    return await super()._do_post(
  File "C:\Users\matve\Desktop\tg_bot_project\venv\lib\site-packages\telegram\_bot.py", line 487, in _do_post
    return await request.post(
  File "C:\Users\matve\Desktop\tg_bot_project\venv\lib\site-packages\telegram\request\_baserequest.py", line 165, in post
    result = await self._request_wrapper(
  File "C:\Users\matve\Desktop\tg_bot_project\venv\lib\site-packages\telegram\request\_baserequest.py", line 330, in _request_wrapper
    raise Conflict(message)
telegram.error.Conflict: Conflict: terminated by other getUpdates request; make sure that only one bot instance is running
2023-04-28 19:32:47,173 - telegram.ext._updater - ERROR - Error while getting Updates: Conflict: terminated by other getUpdates request; make sure that only one bot instance is running
2023-04-28 19:32:47,174 - telegram.ext._application - ERROR - No error handlers are registered, logging exception.
Traceback (most recent call last):
  File "C:\Users\matve\Desktop\tg_bot_project\venv\lib\site-packages\telegram\ext\_updater.py", line 607, in _network_loop_retry
    if not await action_cb():
  File "C:\Users\matve\Desktop\tg_bot_project\venv\lib\site-packages\telegram\ext\_updater.py", line 335, in polling_action_cb
    raise exc
  File "C:\Users\matve\Desktop\tg_bot_project\venv\lib\site-packages\telegram\ext\_updater.py", line 320, in polling_action_cb
    updates = await self.bot.get_updates(
  File "C:\Users\matve\Desktop\tg_bot_project\venv\lib\site-packages\telegram\ext\_extbot.py", line 530, in get_updates
    updates = await super().get_updates(
  File "C:\Users\matve\Desktop\tg_bot_project\venv\lib\site-packages\telegram\_bot.py", line 368, in decorator
    result = await func(*args, **kwargs)  # skipcq: PYL-E1102
  File "C:\Users\matve\Desktop\tg_bot_project\venv\lib\site-packages\telegram\_bot.py", line 3623, in get_updates
    await self._post(
  File "C:\Users\matve\Desktop\tg_bot_project\venv\lib\site-packages\telegram\_bot.py", line 456, in _post
    return await self._do_post(
  File "C:\Users\matve\Desktop\tg_bot_project\venv\lib\site-packages\telegram\ext\_extbot.py", line 312, in _do_post
    return await super()._do_post(
  File "C:\Users\matve\Desktop\tg_bot_project\venv\lib\site-packages\telegram\_bot.py", line 487, in _do_post
    return await request.post(
  File "C:\Users\matve\Desktop\tg_bot_project\venv\lib\site-packages\telegram\request\_baserequest.py", line 165, in post
    result = await self._request_wrapper(
  File "C:\Users\matve\Desktop\tg_bot_project\venv\lib\site-packages\telegram\request\_baserequest.py", line 330, in _request_wrapper
    raise Conflict(message)
telegram.error.Conflict: Conflict: terminated by other getUpdates request; make sure that only one bot instance is running
2023-04-28 19:32:52,897 - telegram.ext._updater - ERROR - Error while getting Updates: Conflict: terminated by other getUpdates request; make sure that only one bot instance is running
2023-04-28 19:32:52,897 - telegram.ext._application - ERROR - No error handlers are registered, logging exception.
Traceback (most recent call last):
  File "C:\Users\matve\Desktop\tg_bot_project\venv\lib\site-packages\telegram\ext\_updater.py", line 607, in _network_loop_retry
    if not await action_cb():
  File "C:\Users\matve\Desktop\tg_bot_project\venv\lib\site-packages\telegram\ext\_updater.py", line 335, in polling_action_cb
    raise exc
  File "C:\Users\matve\Desktop\tg_bot_project\venv\lib\site-packages\telegram\ext\_updater.py", line 320, in polling_action_cb
    updates = await self.bot.get_updates(
  File "C:\Users\matve\Desktop\tg_bot_project\venv\lib\site-packages\telegram\ext\_extbot.py", line 530, in get_updates
    updates = await super().get_updates(
  File "C:\Users\matve\Desktop\tg_bot_project\venv\lib\site-packages\telegram\_bot.py", line 368, in decorator
    result = await func(*args, **kwargs)  # skipcq: PYL-E1102
  File "C:\Users\matve\Desktop\tg_bot_project\venv\lib\site-packages\telegram\_bot.py", line 3623, in get_updates
    await self._post(
  File "C:\Users\matve\Desktop\tg_bot_project\venv\lib\site-packages\telegram\_bot.py", line 456, in _post
    return await self._do_post(
  File "C:\Users\matve\Desktop\tg_bot_project\venv\lib\site-packages\telegram\ext\_extbot.py", line 312, in _do_post
    return await super()._do_post(
  File "C:\Users\matve\Desktop\tg_bot_project\venv\lib\site-packages\telegram\_bot.py", line 487, in _do_post
    return await request.post(
  File "C:\Users\matve\Desktop\tg_bot_project\venv\lib\site-packages\telegram\request\_baserequest.py", line 165, in post
    result = await self._request_wrapper(
  File "C:\Users\matve\Desktop\tg_bot_project\venv\lib\site-packages\telegram\request\_baserequest.py", line 330, in _request_wrapper
    raise Conflict(message)
telegram.error.Conflict: Conflict: terminated by other getUpdates request; make sure that only one bot instance is running
2023-04-28 19:32:58,029 - telegram.ext._updater - ERROR - Error while getting Updates: Conflict: terminated by other getUpdates request; make sure that only one bot instance is running
2023-04-28 19:32:58,030 - telegram.ext._application - ERROR - No error handlers are registered, logging exception.
Traceback (most recent call last):
  File "C:\Users\matve\Desktop\tg_bot_project\venv\lib\site-packages\telegram\ext\_updater.py", line 607, in _network_loop_retry
    if not await action_cb():
  File "C:\Users\matve\Desktop\tg_bot_project\venv\lib\site-packages\telegram\ext\_updater.py", line 335, in polling_action_cb
    raise exc
  File "C:\Users\matve\Desktop\tg_bot_project\venv\lib\site-packages\telegram\ext\_updater.py", line 320, in polling_action_cb
    updates = await self.bot.get_updates(
  File "C:\Users\matve\Desktop\tg_bot_project\venv\lib\site-packages\telegram\ext\_extbot.py", line 530, in get_updates
    updates = await super().get_updates(
  File "C:\Users\matve\Desktop\tg_bot_project\venv\lib\site-packages\telegram\_bot.py", line 368, in decorator
    result = await func(*args, **kwargs)  # skipcq: PYL-E1102
  File "C:\Users\matve\Desktop\tg_bot_project\venv\lib\site-packages\telegram\_bot.py", line 3623, in get_updates
    await self._post(
  File "C:\Users\matve\Desktop\tg_bot_project\venv\lib\site-packages\telegram\_bot.py", line 456, in _post
    return await self._do_post(
  File "C:\Users\matve\Desktop\tg_bot_project\venv\lib\site-packages\telegram\ext\_extbot.py", line 312, in _do_post
    return await super()._do_post(
  File "C:\Users\matve\Desktop\tg_bot_project\venv\lib\site-packages\telegram\_bot.py", line 487, in _do_post
    return await request.post(
  File "C:\Users\matve\Desktop\tg_bot_project\venv\lib\site-packages\telegram\request\_baserequest.py", line 165, in post
    result = await self._request_wrapper(
  File "C:\Users\matve\Desktop\tg_bot_project\venv\lib\site-packages\telegram\request\_baserequest.py", line 330, in _request_wrapper
    raise Conflict(message)
telegram.error.Conflict: Conflict: terminated by other getUpdates request; make sure that only one bot instance is running
2023-04-28 19:33:03,749 - telegram.ext._updater - ERROR - Error while getting Updates: Conflict: terminated by other getUpdates request; make sure that only one bot instance is running
2023-04-28 19:33:03,749 - telegram.ext._application - ERROR - No error handlers are registered, logging exception.
Traceback (most recent call last):
  File "C:\Users\matve\Desktop\tg_bot_project\venv\lib\site-packages\telegram\ext\_updater.py", line 607, in _network_loop_retry
    if not await action_cb():
  File "C:\Users\matve\Desktop\tg_bot_project\venv\lib\site-packages\telegram\ext\_updater.py", line 335, in polling_action_cb
    raise exc
  File "C:\Users\matve\Desktop\tg_bot_project\venv\lib\site-packages\telegram\ext\_updater.py", line 320, in polling_action_cb
    updates = await self.bot.get_updates(
  File "C:\Users\matve\Desktop\tg_bot_project\venv\lib\site-packages\telegram\ext\_extbot.py", line 530, in get_updates
    updates = await super().get_updates(
  File "C:\Users\matve\Desktop\tg_bot_project\venv\lib\site-packages\telegram\_bot.py", line 368, in decorator
    result = await func(*args, **kwargs)  # skipcq: PYL-E1102
  File "C:\Users\matve\Desktop\tg_bot_project\venv\lib\site-packages\telegram\_bot.py", line 3623, in get_updates
    await self._post(
  File "C:\Users\matve\Desktop\tg_bot_project\venv\lib\site-packages\telegram\_bot.py", line 456, in _post
    return await self._do_post(
  File "C:\Users\matve\Desktop\tg_bot_project\venv\lib\site-packages\telegram\ext\_extbot.py", line 312, in _do_post
    return await super()._do_post(
  File "C:\Users\matve\Desktop\tg_bot_project\venv\lib\site-packages\telegram\_bot.py", line 487, in _do_post
    return await request.post(
  File "C:\Users\matve\Desktop\tg_bot_project\venv\lib\site-packages\telegram\request\_baserequest.py", line 165, in post
    result = await self._request_wrapper(
  File "C:\Users\matve\Desktop\tg_bot_project\venv\lib\site-packages\telegram\request\_baserequest.py", line 330, in _request_wrapper
    raise Conflict(message)
telegram.error.Conflict: Conflict: terminated by other getUpdates request; make sure that only one bot instance is running
2023-04-28 19:33:09,404 - telegram.ext._updater - ERROR - Error while getting Updates: Conflict: terminated by other getUpdates request; make sure that only one bot instance is running
2023-04-28 19:33:09,405 - telegram.ext._application - ERROR - No error handlers are registered, logging exception.
Traceback (most recent call last):
  File "C:\Users\matve\Desktop\tg_bot_project\venv\lib\site-packages\telegram\ext\_updater.py", line 607, in _network_loop_retry
    if not await action_cb():
  File "C:\Users\matve\Desktop\tg_bot_project\venv\lib\site-packages\telegram\ext\_updater.py", line 335, in polling_action_cb
    raise exc
  File "C:\Users\matve\Desktop\tg_bot_project\venv\lib\site-packages\telegram\ext\_updater.py", line 320, in polling_action_cb
    updates = await self.bot.get_updates(
  File "C:\Users\matve\Desktop\tg_bot_project\venv\lib\site-packages\telegram\ext\_extbot.py", line 530, in get_updates
    updates = await super().get_updates(
  File "C:\Users\matve\Desktop\tg_bot_project\venv\lib\site-packages\telegram\_bot.py", line 368, in decorator
    result = await func(*args, **kwargs)  # skipcq: PYL-E1102
  File "C:\Users\matve\Desktop\tg_bot_project\venv\lib\site-packages\telegram\_bot.py", line 3623, in get_updates
    await self._post(
  File "C:\Users\matve\Desktop\tg_bot_project\venv\lib\site-packages\telegram\_bot.py", line 456, in _post
    return await self._do_post(
  File "C:\Users\matve\Desktop\tg_bot_project\venv\lib\site-packages\telegram\ext\_extbot.py", line 312, in _do_post
    return await super()._do_post(
  File "C:\Users\matve\Desktop\tg_bot_project\venv\lib\site-packages\telegram\_bot.py", line 487, in _do_post
    return await request.post(
  File "C:\Users\matve\Desktop\tg_bot_project\venv\lib\site-packages\telegram\request\_baserequest.py", line 165, in post
    result = await self._request_wrapper(
  File "C:\Users\matve\Desktop\tg_bot_project\venv\lib\site-packages\telegram\request\_baserequest.py", line 330, in _request_wrapper
    raise Conflict(message)
telegram.error.Conflict: Conflict: terminated by other getUpdates request; make sure that only one bot instance is running
2023-04-28 19:33:15,029 - telegram.ext._updater - ERROR - Error while getting Updates: Conflict: terminated by other getUpdates request; make sure that only one bot instance is running
2023-04-28 19:33:15,030 - telegram.ext._application - ERROR - No error handlers are registered, logging exception.
Traceback (most recent call last):
  File "C:\Users\matve\Desktop\tg_bot_project\venv\lib\site-packages\telegram\ext\_updater.py", line 607, in _network_loop_retry
    if not await action_cb():
  File "C:\Users\matve\Desktop\tg_bot_project\venv\lib\site-packages\telegram\ext\_updater.py", line 335, in polling_action_cb
    raise exc
  File "C:\Users\matve\Desktop\tg_bot_project\venv\lib\site-packages\telegram\ext\_updater.py", line 320, in polling_action_cb
    updates = await self.bot.get_updates(
  File "C:\Users\matve\Desktop\tg_bot_project\venv\lib\site-packages\telegram\ext\_extbot.py", line 530, in get_updates
    updates = await super().get_updates(
  File "C:\Users\matve\Desktop\tg_bot_project\venv\lib\site-packages\telegram\_bot.py", line 368, in decorator
    result = await func(*args, **kwargs)  # skipcq: PYL-E1102
  File "C:\Users\matve\Desktop\tg_bot_project\venv\lib\site-packages\telegram\_bot.py", line 3623, in get_updates
    await self._post(
  File "C:\Users\matve\Desktop\tg_bot_project\venv\lib\site-packages\telegram\_bot.py", line 456, in _post
    return await self._do_post(
  File "C:\Users\matve\Desktop\tg_bot_project\venv\lib\site-packages\telegram\ext\_extbot.py", line 312, in _do_post
    return await super()._do_post(
  File "C:\Users\matve\Desktop\tg_bot_project\venv\lib\site-packages\telegram\_bot.py", line 487, in _do_post
    return await request.post(
  File "C:\Users\matve\Desktop\tg_bot_project\venv\lib\site-packages\telegram\request\_baserequest.py", line 165, in post
    result = await self._request_wrapper(
  File "C:\Users\matve\Desktop\tg_bot_project\venv\lib\site-packages\telegram\request\_baserequest.py", line 330, in _request_wrapper
    raise Conflict(message)
telegram.error.Conflict: Conflict: terminated by other getUpdates request; make sure that only one bot instance is running
2023-04-28 19:33:21,906 - telegram.ext._updater - ERROR - Error while getting Updates: Conflict: terminated by other getUpdates request; make sure that only one bot instance is running
2023-04-28 19:33:21,906 - telegram.ext._application - ERROR - No error handlers are registered, logging exception.
Traceback (most recent call last):
  File "C:\Users\matve\Desktop\tg_bot_project\venv\lib\site-packages\telegram\ext\_updater.py", line 607, in _network_loop_retry
    if not await action_cb():
  File "C:\Users\matve\Desktop\tg_bot_project\venv\lib\site-packages\telegram\ext\_updater.py", line 335, in polling_action_cb
    raise exc
  File "C:\Users\matve\Desktop\tg_bot_project\venv\lib\site-packages\telegram\ext\_updater.py", line 320, in polling_action_cb
    updates = await self.bot.get_updates(
  File "C:\Users\matve\Desktop\tg_bot_project\venv\lib\site-packages\telegram\ext\_extbot.py", line 530, in get_updates
    updates = await super().get_updates(
  File "C:\Users\matve\Desktop\tg_bot_project\venv\lib\site-packages\telegram\_bot.py", line 368, in decorator
    result = await func(*args, **kwargs)  # skipcq: PYL-E1102
  File "C:\Users\matve\Desktop\tg_bot_project\venv\lib\site-packages\telegram\_bot.py", line 3623, in get_updates
    await self._post(
  File "C:\Users\matve\Desktop\tg_bot_project\venv\lib\site-packages\telegram\_bot.py", line 456, in _post
    return await self._do_post(
  File "C:\Users\matve\Desktop\tg_bot_project\venv\lib\site-packages\telegram\ext\_extbot.py", line 312, in _do_post
    return await super()._do_post(
  File "C:\Users\matve\Desktop\tg_bot_project\venv\lib\site-packages\telegram\_bot.py", line 487, in _do_post
    return await request.post(
  File "C:\Users\matve\Desktop\tg_bot_project\venv\lib\site-packages\telegram\request\_baserequest.py", line 165, in post
    result = await self._request_wrapper(
  File "C:\Users\matve\Desktop\tg_bot_project\venv\lib\site-packages\telegram\request\_baserequest.py", line 330, in _request_wrapper
    raise Conflict(message)
telegram.error.Conflict: Conflict: terminated by other getUpdates request; make sure that only one bot instance is running
2023-04-28 19:33:30,689 - telegram.ext._updater - ERROR - Error while getting Updates: Conflict: terminated by other getUpdates request; make sure that only one bot instance is running
2023-04-28 19:33:30,689 - telegram.ext._application - ERROR - No error handlers are registered, logging exception.
Traceback (most recent call last):
  File "C:\Users\matve\Desktop\tg_bot_project\venv\lib\site-packages\telegram\ext\_updater.py", line 607, in _network_loop_retry
    if not await action_cb():
  File "C:\Users\matve\Desktop\tg_bot_project\venv\lib\site-packages\telegram\ext\_updater.py", line 335, in polling_action_cb
    raise exc
  File "C:\Users\matve\Desktop\tg_bot_project\venv\lib\site-packages\telegram\ext\_updater.py", line 320, in polling_action_cb
    updates = await self.bot.get_updates(
  File "C:\Users\matve\Desktop\tg_bot_project\venv\lib\site-packages\telegram\ext\_extbot.py", line 530, in get_updates
    updates = await super().get_updates(
  File "C:\Users\matve\Desktop\tg_bot_project\venv\lib\site-packages\telegram\_bot.py", line 368, in decorator
    result = await func(*args, **kwargs)  # skipcq: PYL-E1102
  File "C:\Users\matve\Desktop\tg_bot_project\venv\lib\site-packages\telegram\_bot.py", line 3623, in get_updates
    await self._post(
  File "C:\Users\matve\Desktop\tg_bot_project\venv\lib\site-packages\telegram\_bot.py", line 456, in _post
    return await self._do_post(
  File "C:\Users\matve\Desktop\tg_bot_project\venv\lib\site-packages\telegram\ext\_extbot.py", line 312, in _do_post
    return await super()._do_post(
  File "C:\Users\matve\Desktop\tg_bot_project\venv\lib\site-packages\telegram\_bot.py", line 487, in _do_post
    return await request.post(
  File "C:\Users\matve\Desktop\tg_bot_project\venv\lib\site-packages\telegram\request\_baserequest.py", line 165, in post
    result = await self._request_wrapper(
  File "C:\Users\matve\Desktop\tg_bot_project\venv\lib\site-packages\telegram\request\_baserequest.py", line 330, in _request_wrapper
    raise Conflict(message)
telegram.error.Conflict: Conflict: terminated by other getUpdates request; make sure that only one bot instance is running
2023-04-28 19:33:39,483 - telegram.ext._updater - ERROR - Error while getting Updates: Conflict: terminated by other getUpdates request; make sure that only one bot instance is running
2023-04-28 19:33:39,484 - telegram.ext._application - ERROR - No error handlers are registered, logging exception.
Traceback (most recent call last):
  File "C:\Users\matve\Desktop\tg_bot_project\venv\lib\site-packages\telegram\ext\_updater.py", line 607, in _network_loop_retry
    if not await action_cb():
  File "C:\Users\matve\Desktop\tg_bot_project\venv\lib\site-packages\telegram\ext\_updater.py", line 335, in polling_action_cb
    raise exc
  File "C:\Users\matve\Desktop\tg_bot_project\venv\lib\site-packages\telegram\ext\_updater.py", line 320, in polling_action_cb
    updates = await self.bot.get_updates(
  File "C:\Users\matve\Desktop\tg_bot_project\venv\lib\site-packages\telegram\ext\_extbot.py", line 530, in get_updates
    updates = await super().get_updates(
  File "C:\Users\matve\Desktop\tg_bot_project\venv\lib\site-packages\telegram\_bot.py", line 368, in decorator
    result = await func(*args, **kwargs)  # skipcq: PYL-E1102
  File "C:\Users\matve\Desktop\tg_bot_project\venv\lib\site-packages\telegram\_bot.py", line 3623, in get_updates
    await self._post(
  File "C:\Users\matve\Desktop\tg_bot_project\venv\lib\site-packages\telegram\_bot.py", line 456, in _post
    return await self._do_post(
  File "C:\Users\matve\Desktop\tg_bot_project\venv\lib\site-packages\telegram\ext\_extbot.py", line 312, in _do_post
    return await super()._do_post(
  File "C:\Users\matve\Desktop\tg_bot_project\venv\lib\site-packages\telegram\_bot.py", line 487, in _do_post
    return await request.post(
  File "C:\Users\matve\Desktop\tg_bot_project\venv\lib\site-packages\telegram\request\_baserequest.py", line 165, in post
    result = await self._request_wrapper(
  File "C:\Users\matve\Desktop\tg_bot_project\venv\lib\site-packages\telegram\request\_baserequest.py", line 330, in _request_wrapper
    raise Conflict(message)
telegram.error.Conflict: Conflict: terminated by other getUpdates request; make sure that only one bot instance is running
2023-04-28 19:33:52,556 - telegram.ext._updater - ERROR - Error while getting Updates: Conflict: terminated by other getUpdates request; make sure that only one bot instance is running
2023-04-28 19:33:52,556 - telegram.ext._application - ERROR - No error handlers are registered, logging exception.
Traceback (most recent call last):
  File "C:\Users\matve\Desktop\tg_bot_project\venv\lib\site-packages\telegram\ext\_updater.py", line 607, in _network_loop_retry
    if not await action_cb():
  File "C:\Users\matve\Desktop\tg_bot_project\venv\lib\site-packages\telegram\ext\_updater.py", line 335, in polling_action_cb
    raise exc
  File "C:\Users\matve\Desktop\tg_bot_project\venv\lib\site-packages\telegram\ext\_updater.py", line 320, in polling_action_cb
    updates = await self.bot.get_updates(
  File "C:\Users\matve\Desktop\tg_bot_project\venv\lib\site-packages\telegram\ext\_extbot.py", line 530, in get_updates
    updates = await super().get_updates(
  File "C:\Users\matve\Desktop\tg_bot_project\venv\lib\site-packages\telegram\_bot.py", line 368, in decorator
    result = await func(*args, **kwargs)  # skipcq: PYL-E1102
  File "C:\Users\matve\Desktop\tg_bot_project\venv\lib\site-packages\telegram\_bot.py", line 3623, in get_updates
    await self._post(
  File "C:\Users\matve\Desktop\tg_bot_project\venv\lib\site-packages\telegram\_bot.py", line 456, in _post
    return await self._do_post(
  File "C:\Users\matve\Desktop\tg_bot_project\venv\lib\site-packages\telegram\ext\_extbot.py", line 312, in _do_post
    return await super()._do_post(
  File "C:\Users\matve\Desktop\tg_bot_project\venv\lib\site-packages\telegram\_bot.py", line 487, in _do_post
    return await request.post(
  File "C:\Users\matve\Desktop\tg_bot_project\venv\lib\site-packages\telegram\request\_baserequest.py", line 165, in post
    result = await self._request_wrapper(
  File "C:\Users\matve\Desktop\tg_bot_project\venv\lib\site-packages\telegram\request\_baserequest.py", line 330, in _request_wrapper
    raise Conflict(message)
telegram.error.Conflict: Conflict: terminated by other getUpdates request; make sure that only one bot instance is running
2023-04-28 19:34:11,887 - telegram.ext._updater - ERROR - Error while getting Updates: Conflict: terminated by other getUpdates request; make sure that only one bot instance is running
2023-04-28 19:34:11,887 - telegram.ext._application - ERROR - No error handlers are registered, logging exception.
Traceback (most recent call last):
  File "C:\Users\matve\Desktop\tg_bot_project\venv\lib\site-packages\telegram\ext\_updater.py", line 607, in _network_loop_retry
    if not await action_cb():
  File "C:\Users\matve\Desktop\tg_bot_project\venv\lib\site-packages\telegram\ext\_updater.py", line 335, in polling_action_cb
    raise exc
  File "C:\Users\matve\Desktop\tg_bot_project\venv\lib\site-packages\telegram\ext\_updater.py", line 320, in polling_action_cb
    updates = await self.bot.get_updates(
  File "C:\Users\matve\Desktop\tg_bot_project\venv\lib\site-packages\telegram\ext\_extbot.py", line 530, in get_updates
    updates = await super().get_updates(
  File "C:\Users\matve\Desktop\tg_bot_project\venv\lib\site-packages\telegram\_bot.py", line 368, in decorator
    result = await func(*args, **kwargs)  # skipcq: PYL-E1102
  File "C:\Users\matve\Desktop\tg_bot_project\venv\lib\site-packages\telegram\_bot.py", line 3623, in get_updates
    await self._post(
  File "C:\Users\matve\Desktop\tg_bot_project\venv\lib\site-packages\telegram\_bot.py", line 456, in _post
    return await self._do_post(
  File "C:\Users\matve\Desktop\tg_bot_project\venv\lib\site-packages\telegram\ext\_extbot.py", line 312, in _do_post
    return await super()._do_post(
  File "C:\Users\matve\Desktop\tg_bot_project\venv\lib\site-packages\telegram\_bot.py", line 487, in _do_post
    return await request.post(
  File "C:\Users\matve\Desktop\tg_bot_project\venv\lib\site-packages\telegram\request\_baserequest.py", line 165, in post
    result = await self._request_wrapper(
  File "C:\Users\matve\Desktop\tg_bot_project\venv\lib\site-packages\telegram\request\_baserequest.py", line 330, in _request_wrapper
    raise Conflict(message)
telegram.error.Conflict: Conflict: terminated by other getUpdates request; make sure that only one bot instance is running
2023-04-28 19:34:33,227 - telegram.ext._updater - ERROR - Error while getting Updates: Conflict: terminated by other getUpdates request; make sure that only one bot instance is running
2023-04-28 19:34:33,227 - telegram.ext._application - ERROR - No error handlers are registered, logging exception.
Traceback (most recent call last):
  File "C:\Users\matve\Desktop\tg_bot_project\venv\lib\site-packages\telegram\ext\_updater.py", line 607, in _network_loop_retry
    if not await action_cb():
  File "C:\Users\matve\Desktop\tg_bot_project\venv\lib\site-packages\telegram\ext\_updater.py", line 335, in polling_action_cb
    raise exc
  File "C:\Users\matve\Desktop\tg_bot_project\venv\lib\site-packages\telegram\ext\_updater.py", line 320, in polling_action_cb
    updates = await self.bot.get_updates(
  File "C:\Users\matve\Desktop\tg_bot_project\venv\lib\site-packages\telegram\ext\_extbot.py", line 530, in get_updates
    updates = await super().get_updates(
  File "C:\Users\matve\Desktop\tg_bot_project\venv\lib\site-packages\telegram\_bot.py", line 368, in decorator
    result = await func(*args, **kwargs)  # skipcq: PYL-E1102
  File "C:\Users\matve\Desktop\tg_bot_project\venv\lib\site-packages\telegram\_bot.py", line 3623, in get_updates
    await self._post(
  File "C:\Users\matve\Desktop\tg_bot_project\venv\lib\site-packages\telegram\_bot.py", line 456, in _post
    return await self._do_post(
  File "C:\Users\matve\Desktop\tg_bot_project\venv\lib\site-packages\telegram\ext\_extbot.py", line 312, in _do_post
    return await super()._do_post(
  File "C:\Users\matve\Desktop\tg_bot_project\venv\lib\site-packages\telegram\_bot.py", line 487, in _do_post
    return await request.post(
  File "C:\Users\matve\Desktop\tg_bot_project\venv\lib\site-packages\telegram\request\_baserequest.py", line 165, in post
    result = await self._request_wrapper(
  File "C:\Users\matve\Desktop\tg_bot_project\venv\lib\site-packages\telegram\request\_baserequest.py", line 330, in _request_wrapper
    raise Conflict(message)
telegram.error.Conflict: Conflict: terminated by other getUpdates request; make sure that only one bot instance is running
2023-04-28 19:35:02,703 - telegram.ext._updater - ERROR - Error while getting Updates: Conflict: terminated by other getUpdates request; make sure that only one bot instance is running
2023-04-28 19:35:02,704 - telegram.ext._application - ERROR - No error handlers are registered, logging exception.
Traceback (most recent call last):
  File "C:\Users\matve\Desktop\tg_bot_project\venv\lib\site-packages\telegram\ext\_updater.py", line 607, in _network_loop_retry
    if not await action_cb():
  File "C:\Users\matve\Desktop\tg_bot_project\venv\lib\site-packages\telegram\ext\_updater.py", line 335, in polling_action_cb
    raise exc
  File "C:\Users\matve\Desktop\tg_bot_project\venv\lib\site-packages\telegram\ext\_updater.py", line 320, in polling_action_cb
    updates = await self.bot.get_updates(
  File "C:\Users\matve\Desktop\tg_bot_project\venv\lib\site-packages\telegram\ext\_extbot.py", line 530, in get_updates
    updates = await super().get_updates(
  File "C:\Users\matve\Desktop\tg_bot_project\venv\lib\site-packages\telegram\_bot.py", line 368, in decorator
    result = await func(*args, **kwargs)  # skipcq: PYL-E1102
  File "C:\Users\matve\Desktop\tg_bot_project\venv\lib\site-packages\telegram\_bot.py", line 3623, in get_updates
    await self._post(
  File "C:\Users\matve\Desktop\tg_bot_project\venv\lib\site-packages\telegram\_bot.py", line 456, in _post
    return await self._do_post(
  File "C:\Users\matve\Desktop\tg_bot_project\venv\lib\site-packages\telegram\ext\_extbot.py", line 312, in _do_post
    return await super()._do_post(
  File "C:\Users\matve\Desktop\tg_bot_project\venv\lib\site-packages\telegram\_bot.py", line 487, in _do_post
    return await request.post(
  File "C:\Users\matve\Desktop\tg_bot_project\venv\lib\site-packages\telegram\request\_baserequest.py", line 165, in post
    result = await self._request_wrapper(
  File "C:\Users\matve\Desktop\tg_bot_project\venv\lib\site-packages\telegram\request\_baserequest.py", line 330, in _request_wrapper
    raise Conflict(message)
telegram.error.Conflict: Conflict: terminated by other getUpdates request; make sure that only one bot instance is running
2023-04-28 19:35:04,391 - telegram.ext._application - INFO - Application is stopping. This might take a moment.
2023-04-28 19:35:04,392 - telegram.ext._application - INFO - Application.stop() complete
2023-04-28 19:47:06,515 - telegram.ext._application - INFO - Application started
2023-04-28 19:49:02,622 - telegram.ext._application - INFO - Application is stopping. This might take a moment.
2023-04-28 19:49:02,622 - telegram.ext._application - INFO - Application.stop() complete
2023-04-28 19:49:27,581 - telegram.ext._application - INFO - Application started
2023-04-28 19:50:12,853 - telegram.ext._application - INFO - Application is stopping. This might take a moment.
2023-04-28 19:50:12,853 - telegram.ext._application - INFO - Application.stop() complete
