2023-04-29 03:21:52,799 - telegram.ext._application - INFO - Application started
2023-04-29 03:22:28,055 - telegram.ext._application - INFO - Application is stopping. This might take a moment.
2023-04-29 03:22:28,055 - telegram.ext._application - INFO - Application.stop() complete
2023-04-29 03:22:49,931 - telegram.ext._application - INFO - Application started
2023-04-29 03:22:59,823 - telegram.ext._application - ERROR - No error handlers are registered, logging exception.
Traceback (most recent call last):
  File "C:\Users\matve\Desktop\tg_bot_project\venv\lib\site-packages\telegram\ext\_application.py", line 1115, in process_update
    await coroutine
  File "C:\Users\matve\Desktop\tg_bot_project\venv\lib\site-packages\telegram\ext\_conversationhandler.py", line 826, in handle_update
    new_state: object = await handler.handle_update(
  File "C:\Users\matve\Desktop\tg_bot_project\venv\lib\site-packages\telegram\ext\_handler.py", line 141, in handle_update
    return await self.callback(update, context)
  File "C:\Users\matve\Desktop\tg_bot_project\output\app.py", line 475, in change_date
    text, for_robot = await get_weather(self.response, self.name_from, date=int(num) - 3)
  File "C:\Users\matve\Desktop\tg_bot_project\output\funcs_backend.py", line 251, in get_weather
    text += f"Ощущаемая температура °C: \U0001f321{now['feels_like']}\n"
KeyError: 'feels_like'
2023-04-29 03:23:02,128 - telegram.ext._application - ERROR - No error handlers are registered, logging exception.
Traceback (most recent call last):
  File "C:\Users\matve\Desktop\tg_bot_project\venv\lib\site-packages\telegram\ext\_application.py", line 1115, in process_update
    await coroutine
  File "C:\Users\matve\Desktop\tg_bot_project\venv\lib\site-packages\telegram\ext\_conversationhandler.py", line 826, in handle_update
    new_state: object = await handler.handle_update(
  File "C:\Users\matve\Desktop\tg_bot_project\venv\lib\site-packages\telegram\ext\_handler.py", line 141, in handle_update
    return await self.callback(update, context)
  File "C:\Users\matve\Desktop\tg_bot_project\output\app.py", line 475, in change_date
    text, for_robot = await get_weather(self.response, self.name_from, date=int(num) - 3)
  File "C:\Users\matve\Desktop\tg_bot_project\output\funcs_backend.py", line 251, in get_weather
    text += f"Ощущаемая температура °C: \U0001f321{now['feels_like']}\n"
KeyError: 'feels_like'
2023-04-29 03:23:49,442 - telegram.ext._application - ERROR - No error handlers are registered, logging exception.
Traceback (most recent call last):
  File "C:\Users\matve\Desktop\tg_bot_project\venv\lib\site-packages\telegram\ext\_application.py", line 1115, in process_update
    await coroutine
  File "C:\Users\matve\Desktop\tg_bot_project\venv\lib\site-packages\telegram\ext\_conversationhandler.py", line 826, in handle_update
    new_state: object = await handler.handle_update(
  File "C:\Users\matve\Desktop\tg_bot_project\venv\lib\site-packages\telegram\ext\_handler.py", line 141, in handle_update
    return await self.callback(update, context)
  File "C:\Users\matve\Desktop\tg_bot_project\output\app.py", line 475, in change_date
    text, for_robot = await get_weather(self.response, self.name_from, date=int(num) - 3)
  File "C:\Users\matve\Desktop\tg_bot_project\output\funcs_backend.py", line 251, in get_weather
    text += f"Ощущаемая температура °C: \U0001f321{now['feels_like']}\n"
KeyError: 'feels_like'
2023-04-29 03:23:52,832 - telegram.ext._application - ERROR - No error handlers are registered, logging exception.
Traceback (most recent call last):
  File "C:\Users\matve\Desktop\tg_bot_project\venv\lib\site-packages\telegram\ext\_application.py", line 1115, in process_update
    await coroutine
  File "C:\Users\matve\Desktop\tg_bot_project\venv\lib\site-packages\telegram\ext\_conversationhandler.py", line 826, in handle_update
    new_state: object = await handler.handle_update(
  File "C:\Users\matve\Desktop\tg_bot_project\venv\lib\site-packages\telegram\ext\_handler.py", line 141, in handle_update
    return await self.callback(update, context)
  File "C:\Users\matve\Desktop\tg_bot_project\output\app.py", line 475, in change_date
    text, for_robot = await get_weather(self.response, self.name_from, date=int(num) - 3)
  File "C:\Users\matve\Desktop\tg_bot_project\output\funcs_backend.py", line 251, in get_weather
    text += f"Ощущаемая температура °C: \U0001f321{now['feels_like']}\n"
KeyError: 'feels_like'
2023-04-29 03:23:53,673 - telegram.ext._application - ERROR - No error handlers are registered, logging exception.
Traceback (most recent call last):
  File "C:\Users\matve\Desktop\tg_bot_project\venv\lib\site-packages\telegram\ext\_application.py", line 1115, in process_update
    await coroutine
  File "C:\Users\matve\Desktop\tg_bot_project\venv\lib\site-packages\telegram\ext\_conversationhandler.py", line 826, in handle_update
    new_state: object = await handler.handle_update(
  File "C:\Users\matve\Desktop\tg_bot_project\venv\lib\site-packages\telegram\ext\_handler.py", line 141, in handle_update
    return await self.callback(update, context)
  File "C:\Users\matve\Desktop\tg_bot_project\output\app.py", line 475, in change_date
    text, for_robot = await get_weather(self.response, self.name_from, date=int(num) - 3)
  File "C:\Users\matve\Desktop\tg_bot_project\output\funcs_backend.py", line 251, in get_weather
    text += f"Ощущаемая температура °C: \U0001f321{now['feels_like']}\n"
KeyError: 'feels_like'
2023-04-29 03:23:54,454 - telegram.ext._application - ERROR - No error handlers are registered, logging exception.
Traceback (most recent call last):
  File "C:\Users\matve\Desktop\tg_bot_project\venv\lib\site-packages\telegram\ext\_application.py", line 1115, in process_update
    await coroutine
  File "C:\Users\matve\Desktop\tg_bot_project\venv\lib\site-packages\telegram\ext\_conversationhandler.py", line 826, in handle_update
    new_state: object = await handler.handle_update(
  File "C:\Users\matve\Desktop\tg_bot_project\venv\lib\site-packages\telegram\ext\_handler.py", line 141, in handle_update
    return await self.callback(update, context)
  File "C:\Users\matve\Desktop\tg_bot_project\output\app.py", line 475, in change_date
    text, for_robot = await get_weather(self.response, self.name_from, date=int(num) - 3)
  File "C:\Users\matve\Desktop\tg_bot_project\output\funcs_backend.py", line 251, in get_weather
    text += f"Ощущаемая температура °C: \U0001f321{now['feels_like']}\n"
KeyError: 'feels_like'
2023-04-29 03:23:55,054 - telegram.ext._application - ERROR - No error handlers are registered, logging exception.
Traceback (most recent call last):
  File "C:\Users\matve\Desktop\tg_bot_project\venv\lib\site-packages\telegram\ext\_application.py", line 1115, in process_update
    await coroutine
  File "C:\Users\matve\Desktop\tg_bot_project\venv\lib\site-packages\telegram\ext\_conversationhandler.py", line 826, in handle_update
    new_state: object = await handler.handle_update(
  File "C:\Users\matve\Desktop\tg_bot_project\venv\lib\site-packages\telegram\ext\_handler.py", line 141, in handle_update
    return await self.callback(update, context)
  File "C:\Users\matve\Desktop\tg_bot_project\output\app.py", line 475, in change_date
    text, for_robot = await get_weather(self.response, self.name_from, date=int(num) - 3)
  File "C:\Users\matve\Desktop\tg_bot_project\output\funcs_backend.py", line 251, in get_weather
    text += f"Ощущаемая температура °C: \U0001f321{now['feels_like']}\n"
KeyError: 'feels_like'
2023-04-29 03:23:55,479 - telegram.ext._application - ERROR - No error handlers are registered, logging exception.
Traceback (most recent call last):
  File "C:\Users\matve\Desktop\tg_bot_project\venv\lib\site-packages\telegram\ext\_application.py", line 1115, in process_update
    await coroutine
  File "C:\Users\matve\Desktop\tg_bot_project\venv\lib\site-packages\telegram\ext\_conversationhandler.py", line 826, in handle_update
    new_state: object = await handler.handle_update(
  File "C:\Users\matve\Desktop\tg_bot_project\venv\lib\site-packages\telegram\ext\_handler.py", line 141, in handle_update
    return await self.callback(update, context)
  File "C:\Users\matve\Desktop\tg_bot_project\output\app.py", line 475, in change_date
    text, for_robot = await get_weather(self.response, self.name_from, date=int(num) - 3)
  File "C:\Users\matve\Desktop\tg_bot_project\output\funcs_backend.py", line 251, in get_weather
    text += f"Ощущаемая температура °C: \U0001f321{now['feels_like']}\n"
KeyError: 'feels_like'
2023-04-29 03:24:17,568 - telegram.ext._application - INFO - Application is stopping. This might take a moment.
2023-04-29 03:24:17,569 - telegram.ext._application - INFO - Application.stop() complete
2023-04-29 03:24:22,312 - telegram.ext._application - INFO - Application started
2023-04-29 03:24:42,273 - telegram.ext._application - ERROR - No error handlers are registered, logging exception.
Traceback (most recent call last):
  File "C:\Users\matve\Desktop\tg_bot_project\venv\lib\site-packages\telegram\ext\_application.py", line 1115, in process_update
    await coroutine
  File "C:\Users\matve\Desktop\tg_bot_project\venv\lib\site-packages\telegram\ext\_conversationhandler.py", line 826, in handle_update
    new_state: object = await handler.handle_update(
  File "C:\Users\matve\Desktop\tg_bot_project\venv\lib\site-packages\telegram\ext\_handler.py", line 141, in handle_update
    return await self.callback(update, context)
  File "C:\Users\matve\Desktop\tg_bot_project\output\app.py", line 475, in change_date
    text, for_robot = await get_weather(self.response, self.name_from, date=int(num) - 3)
  File "C:\Users\matve\Desktop\tg_bot_project\output\funcs_backend.py", line 250, in get_weather
    now = response["forecasts"][date]["day"]
KeyError: 'day'
2023-04-29 03:24:44,082 - telegram.ext._application - ERROR - No error handlers are registered, logging exception.
Traceback (most recent call last):
  File "C:\Users\matve\Desktop\tg_bot_project\venv\lib\site-packages\telegram\ext\_application.py", line 1115, in process_update
    await coroutine
  File "C:\Users\matve\Desktop\tg_bot_project\venv\lib\site-packages\telegram\ext\_conversationhandler.py", line 826, in handle_update
    new_state: object = await handler.handle_update(
  File "C:\Users\matve\Desktop\tg_bot_project\venv\lib\site-packages\telegram\ext\_handler.py", line 141, in handle_update
    return await self.callback(update, context)
  File "C:\Users\matve\Desktop\tg_bot_project\output\app.py", line 475, in change_date
    text, for_robot = await get_weather(self.response, self.name_from, date=int(num) - 3)
  File "C:\Users\matve\Desktop\tg_bot_project\output\funcs_backend.py", line 250, in get_weather
    now = response["forecasts"][date]["day"]
KeyError: 'day'
2023-04-29 03:25:22,197 - telegram.ext._application - INFO - Application is stopping. This might take a moment.
2023-04-29 03:25:22,198 - telegram.ext._application - INFO - Application.stop() complete
2023-04-29 03:25:26,977 - telegram.ext._application - INFO - Application started
2023-04-29 03:25:36,676 - telegram.ext._application - ERROR - No error handlers are registered, logging exception.
Traceback (most recent call last):
  File "C:\Users\matve\Desktop\tg_bot_project\venv\lib\site-packages\telegram\ext\_application.py", line 1115, in process_update
    await coroutine
  File "C:\Users\matve\Desktop\tg_bot_project\venv\lib\site-packages\telegram\ext\_conversationhandler.py", line 826, in handle_update
    new_state: object = await handler.handle_update(
  File "C:\Users\matve\Desktop\tg_bot_project\venv\lib\site-packages\telegram\ext\_handler.py", line 141, in handle_update
    return await self.callback(update, context)
  File "C:\Users\matve\Desktop\tg_bot_project\output\app.py", line 475, in change_date
    text, for_robot = await get_weather(self.response, self.name_from, date=int(num) - 3)
  File "C:\Users\matve\Desktop\tg_bot_project\output\funcs_backend.py", line 250, in get_weather
    now = response["forecasts"][0]["day"]
KeyError: 'day'
2023-04-29 03:25:41,292 - telegram.ext._application - ERROR - No error handlers are registered, logging exception.
Traceback (most recent call last):
  File "C:\Users\matve\Desktop\tg_bot_project\venv\lib\site-packages\telegram\ext\_application.py", line 1115, in process_update
    await coroutine
  File "C:\Users\matve\Desktop\tg_bot_project\venv\lib\site-packages\telegram\ext\_conversationhandler.py", line 826, in handle_update
    new_state: object = await handler.handle_update(
  File "C:\Users\matve\Desktop\tg_bot_project\venv\lib\site-packages\telegram\ext\_handler.py", line 141, in handle_update
    return await self.callback(update, context)
  File "C:\Users\matve\Desktop\tg_bot_project\output\app.py", line 475, in change_date
    text, for_robot = await get_weather(self.response, self.name_from, date=int(num) - 3)
  File "C:\Users\matve\Desktop\tg_bot_project\output\funcs_backend.py", line 250, in get_weather
    now = response["forecasts"][0]["day"]
KeyError: 'day'
2023-04-29 03:25:42,852 - telegram.ext._application - ERROR - No error handlers are registered, logging exception.
Traceback (most recent call last):
  File "C:\Users\matve\Desktop\tg_bot_project\venv\lib\site-packages\telegram\ext\_application.py", line 1115, in process_update
    await coroutine
  File "C:\Users\matve\Desktop\tg_bot_project\venv\lib\site-packages\telegram\ext\_conversationhandler.py", line 826, in handle_update
    new_state: object = await handler.handle_update(
  File "C:\Users\matve\Desktop\tg_bot_project\venv\lib\site-packages\telegram\ext\_handler.py", line 141, in handle_update
    return await self.callback(update, context)
  File "C:\Users\matve\Desktop\tg_bot_project\output\app.py", line 475, in change_date
    text, for_robot = await get_weather(self.response, self.name_from, date=int(num) - 3)
  File "C:\Users\matve\Desktop\tg_bot_project\output\funcs_backend.py", line 250, in get_weather
    now = response["forecasts"][0]["day"]
KeyError: 'day'
2023-04-29 03:27:08,546 - telegram.ext._application - INFO - Application is stopping. This might take a moment.
2023-04-29 03:27:08,547 - telegram.ext._application - INFO - Application.stop() complete
2023-04-29 03:27:12,742 - telegram.ext._application - INFO - Application started
2023-04-29 03:28:13,620 - asyncio - ERROR - Unclosed client session
client_session: <aiohttp.client.ClientSession object at 0x000001FFCEBA87C0>
2023-04-29 03:28:13,620 - asyncio - ERROR - Unclosed connector
connections: ['[(<aiohttp.client_proto.ResponseHandler object at 0x000001FFCEAEE340>, 1261332.531)]']
connector: <aiohttp.connector.TCPConnector object at 0x000001FFCEBA8A00>
2023-04-29 03:28:41,674 - asyncio - ERROR - Unclosed client session
client_session: <aiohttp.client.ClientSession object at 0x000001FFCECC0DC0>
2023-04-29 03:28:41,674 - asyncio - ERROR - Unclosed connector
connections: ['[(<aiohttp.client_proto.ResponseHandler object at 0x000001FFCECC2400>, 1261360.656)]']
connector: <aiohttp.connector.TCPConnector object at 0x000001FFCECA8A90>
2023-04-29 03:28:48,868 - asyncio - ERROR - Unclosed client session
client_session: <aiohttp.client.ClientSession object at 0x000001FFCEDC5430>
2023-04-29 03:28:48,868 - asyncio - ERROR - Unclosed connector
connections: ['[(<aiohttp.client_proto.ResponseHandler object at 0x000001FFCECC2E20>, 1261367.843)]']
connector: <aiohttp.connector.TCPConnector object at 0x000001FFCECC10D0>
2023-04-29 03:28:52,563 - asyncio - ERROR - Unclosed client session
client_session: <aiohttp.client.ClientSession object at 0x000001FFCED56940>
2023-04-29 03:28:52,564 - asyncio - ERROR - Unclosed connector
connections: ['[(<aiohttp.client_proto.ResponseHandler object at 0x000001FFCEBAB5E0>, 1261371.531)]']
connector: <aiohttp.connector.TCPConnector object at 0x000001FFCECC00D0>
2023-04-29 03:31:49,168 - telegram.ext._application - INFO - Application is stopping. This might take a moment.
2023-04-29 03:31:49,169 - telegram.ext._application - INFO - Application.stop() complete
2023-04-29 03:58:09,482 - asyncio - ERROR - Unclosed client session
client_session: <aiohttp.client.ClientSession object at 0x11ff31ba0>
2023-04-29 03:58:14,531 - telegram.ext._application - INFO - Application started
2023-04-29 03:58:53,668 - telegram.ext._application - INFO - Application is stopping. This might take a moment.
2023-04-29 03:58:53,668 - telegram.ext._application - INFO - Application.stop() complete
2023-04-29 03:58:53,741 - asyncio - ERROR - Unclosed client session
client_session: <aiohttp.client.ClientSession object at 0x12756f7f0>
2023-04-29 03:58:54,943 - telegram.ext._application - INFO - Application started
2023-04-29 03:59:36,828 - asyncio - ERROR - Unclosed client session
client_session: <aiohttp.client.ClientSession object at 0x125a18190>
2023-04-29 03:59:36,830 - asyncio - ERROR - Unclosed connector
connections: ['[(<aiohttp.client_proto.ResponseHandler object at 0x125a0b520>, 886557.786815666)]']
connector: <aiohttp.connector.TCPConnector object at 0x12579ea40>
2023-04-29 03:59:42,681 - asyncio - ERROR - Unclosed client session
client_session: <aiohttp.client.ClientSession object at 0x1258053f0>
2023-04-29 03:59:42,682 - asyncio - ERROR - Unclosed connector
connections: ['[(<aiohttp.client_proto.ResponseHandler object at 0x12576dd20>, 886563.640229791)]']
connector: <aiohttp.connector.TCPConnector object at 0x12579e860>
2023-04-29 03:59:58,431 - asyncio - ERROR - Unclosed client session
client_session: <aiohttp.client.ClientSession object at 0x125b80970>
2023-04-29 03:59:58,432 - asyncio - ERROR - Unclosed connector
connections: ['[(<aiohttp.client_proto.ResponseHandler object at 0x125b7d5a0>, 886579.389120875)]']
connector: <aiohttp.connector.TCPConnector object at 0x12579fb50>
2023-04-29 04:00:00,371 - asyncio - ERROR - Unclosed client session
client_session: <aiohttp.client.ClientSession object at 0x125d40b80>
2023-04-29 04:00:00,371 - asyncio - ERROR - Unclosed connector
connections: ['[(<aiohttp.client_proto.ResponseHandler object at 0x125b7e0e0>, 886581.33077)]']
connector: <aiohttp.connector.TCPConnector object at 0x125d41600>
2023-04-29 04:00:05,616 - asyncio - ERROR - Unclosed client session
client_session: <aiohttp.client.ClientSession object at 0x125da5480>
2023-04-29 04:00:05,616 - asyncio - ERROR - Unclosed connector
connections: ['[(<aiohttp.client_proto.ResponseHandler object at 0x125b7ec80>, 886586.574734291)]']
connector: <aiohttp.connector.TCPConnector object at 0x125d41e70>
2023-04-29 04:01:15,145 - matplotlib.category - INFO - Using categorical units to plot a list of strings that are all parsable as floats or dates. If these strings should be plotted as numbers, cast to the appropriate data type before plotting.
2023-04-29 04:01:15,145 - matplotlib.category - INFO - Using categorical units to plot a list of strings that are all parsable as floats or dates. If these strings should be plotted as numbers, cast to the appropriate data type before plotting.
2023-04-29 04:01:15,147 - matplotlib.category - INFO - Using categorical units to plot a list of strings that are all parsable as floats or dates. If these strings should be plotted as numbers, cast to the appropriate data type before plotting.
2023-04-29 04:04:00,286 - telegram.ext._application - INFO - Application is stopping. This might take a moment.
2023-04-29 04:04:00,287 - telegram.ext._application - INFO - Application.stop() complete
2023-04-29 04:04:00,363 - asyncio - ERROR - Unclosed client session
client_session: <aiohttp.client.ClientSession object at 0x12516fa60>
2023-04-29 16:45:32,353 - telegram.ext._application - INFO - Application started
2023-04-29 16:45:58,179 - telegram.ext._application - INFO - Application is stopping. This might take a moment.
2023-04-29 16:45:58,180 - telegram.ext._application - INFO - Application.stop() complete
2023-04-29 16:45:58,251 - asyncio - ERROR - Unclosed client session
client_session: <aiohttp.client.ClientSession object at 0x12eb898d0>
2023-04-29 16:54:44,109 - telegram.ext._application - INFO - Application started
2023-04-29 16:54:57,950 - telegram.ext._application - ERROR - No error handlers are registered, logging exception.
Traceback (most recent call last):
  File "/Users/nikita/PycharmProjects/tg_bot_project/venv/lib/python3.10/site-packages/telegram/request/_baserequest.py", line 274, in _request_wrapper
    code, payload = await self.do_request(
  File "/Users/nikita/PycharmProjects/tg_bot_project/venv/lib/python3.10/site-packages/telegram/request/_httpxrequest.py", line 213, in do_request
    data = request_data.json_parameters if request_data else None
  File "/Users/nikita/PycharmProjects/tg_bot_project/venv/lib/python3.10/site-packages/telegram/request/_requestdata.py", line 73, in json_parameters
    return {
  File "/Users/nikita/PycharmProjects/tg_bot_project/venv/lib/python3.10/site-packages/telegram/request/_requestdata.py", line 76, in <dictcomp>
    if param.json_value is not None
  File "/Users/nikita/PycharmProjects/tg_bot_project/venv/lib/python3.10/site-packages/telegram/request/_requestparameter.py", line 75, in json_value
    return json.dumps(self.value)
  File "/Library/Frameworks/Python.framework/Versions/3.10/lib/python3.10/json/__init__.py", line 231, in dumps
    return _default_encoder.encode(obj)
  File "/Library/Frameworks/Python.framework/Versions/3.10/lib/python3.10/json/encoder.py", line 199, in encode
    chunks = self.iterencode(o, _one_shot=True)
  File "/Library/Frameworks/Python.framework/Versions/3.10/lib/python3.10/json/encoder.py", line 257, in iterencode
    return _iterencode(o, 0)
  File "/Library/Frameworks/Python.framework/Versions/3.10/lib/python3.10/json/encoder.py", line 179, in default
    raise TypeError(f'Object of type {o.__class__.__name__} '
TypeError: Object of type coroutine is not JSON serializable

The above exception was the direct cause of the following exception:

Traceback (most recent call last):
  File "/Users/nikita/PycharmProjects/tg_bot_project/venv/lib/python3.10/site-packages/telegram/ext/_application.py", line 1115, in process_update
    await coroutine
  File "/Users/nikita/PycharmProjects/tg_bot_project/venv/lib/python3.10/site-packages/telegram/ext/_conversationhandler.py", line 826, in handle_update
    new_state: object = await handler.handle_update(
  File "/Users/nikita/PycharmProjects/tg_bot_project/venv/lib/python3.10/site-packages/telegram/ext/_handler.py", line 141, in handle_update
    return await self.callback(update, context)
  File "/Users/nikita/PycharmProjects/tg_bot_project/tg_bot_project/output/app.py", line 462, in weather_start
    await update.message.reply_text('РџСЂРёРІРµС‚. Р§С‚РѕР±С‹ СѓР·РЅР°С‚СЊ РёРЅС„РѕСЂРјР°С†РёСЋ Рѕ РїРѕРіРѕРґРµ, РІС‹Р±РµСЂРё, РєР°Рє С‚С‹ РїСЂРёС€Р»РµС€СЊ'
  File "/Users/nikita/PycharmProjects/tg_bot_project/venv/lib/python3.10/site-packages/telegram/_message.py", line 1041, in reply_text
    return await self.get_bot().send_message(
  File "/Users/nikita/PycharmProjects/tg_bot_project/venv/lib/python3.10/site-packages/telegram/ext/_extbot.py", line 2618, in send_message
    return await super().send_message(
  File "/Users/nikita/PycharmProjects/tg_bot_project/venv/lib/python3.10/site-packages/telegram/_bot.py", line 368, in decorator
    result = await func(*args, **kwargs)  # skipcq: PYL-E1102
  File "/Users/nikita/PycharmProjects/tg_bot_project/venv/lib/python3.10/site-packages/telegram/_bot.py", line 797, in send_message
    return await self._send_message(
  File "/Users/nikita/PycharmProjects/tg_bot_project/venv/lib/python3.10/site-packages/telegram/ext/_extbot.py", line 494, in _send_message
    result = await super()._send_message(
  File "/Users/nikita/PycharmProjects/tg_bot_project/venv/lib/python3.10/site-packages/telegram/_bot.py", line 549, in _send_message
    result = await self._post(
  File "/Users/nikita/PycharmProjects/tg_bot_project/venv/lib/python3.10/site-packages/telegram/_bot.py", line 456, in _post
    return await self._do_post(
  File "/Users/nikita/PycharmProjects/tg_bot_project/venv/lib/python3.10/site-packages/telegram/ext/_extbot.py", line 312, in _do_post
    return await super()._do_post(
  File "/Users/nikita/PycharmProjects/tg_bot_project/venv/lib/python3.10/site-packages/telegram/_bot.py", line 487, in _do_post
    return await request.post(
  File "/Users/nikita/PycharmProjects/tg_bot_project/venv/lib/python3.10/site-packages/telegram/request/_baserequest.py", line 165, in post
    result = await self._request_wrapper(
  File "/Users/nikita/PycharmProjects/tg_bot_project/venv/lib/python3.10/site-packages/telegram/request/_baserequest.py", line 290, in _request_wrapper
    raise NetworkError(f"Unknown error in HTTP implementation: {repr(exc)}") from exc
telegram.error.NetworkError: Unknown error in HTTP implementation: TypeError('Object of type coroutine is not JSON serializable')
2023-04-29 16:56:07,500 - telegram.ext._application - INFO - Application is stopping. This might take a moment.
2023-04-29 16:56:07,501 - telegram.ext._application - INFO - Application.stop() complete
2023-04-29 16:56:07,571 - asyncio - ERROR - Unclosed client session
client_session: <aiohttp.client.ClientSession object at 0x160b82200>
2023-04-29 16:56:08,887 - telegram.ext._application - INFO - Application started
2023-04-29 16:56:11,635 - telegram.ext._application - ERROR - No error handlers are registered, logging exception.
Traceback (most recent call last):
  File "/Users/nikita/PycharmProjects/tg_bot_project/venv/lib/python3.10/site-packages/telegram/request/_baserequest.py", line 274, in _request_wrapper
    code, payload = await self.do_request(
  File "/Users/nikita/PycharmProjects/tg_bot_project/venv/lib/python3.10/site-packages/telegram/request/_httpxrequest.py", line 213, in do_request
    data = request_data.json_parameters if request_data else None
  File "/Users/nikita/PycharmProjects/tg_bot_project/venv/lib/python3.10/site-packages/telegram/request/_requestdata.py", line 73, in json_parameters
    return {
  File "/Users/nikita/PycharmProjects/tg_bot_project/venv/lib/python3.10/site-packages/telegram/request/_requestdata.py", line 76, in <dictcomp>
    if param.json_value is not None
  File "/Users/nikita/PycharmProjects/tg_bot_project/venv/lib/python3.10/site-packages/telegram/request/_requestparameter.py", line 75, in json_value
    return json.dumps(self.value)
  File "/Library/Frameworks/Python.framework/Versions/3.10/lib/python3.10/json/__init__.py", line 231, in dumps
    return _default_encoder.encode(obj)
  File "/Library/Frameworks/Python.framework/Versions/3.10/lib/python3.10/json/encoder.py", line 199, in encode
    chunks = self.iterencode(o, _one_shot=True)
  File "/Library/Frameworks/Python.framework/Versions/3.10/lib/python3.10/json/encoder.py", line 257, in iterencode
    return _iterencode(o, 0)
  File "/Library/Frameworks/Python.framework/Versions/3.10/lib/python3.10/json/encoder.py", line 179, in default
    raise TypeError(f'Object of type {o.__class__.__name__} '
TypeError: Object of type coroutine is not JSON serializable

The above exception was the direct cause of the following exception:

Traceback (most recent call last):
  File "/Users/nikita/PycharmProjects/tg_bot_project/venv/lib/python3.10/site-packages/telegram/ext/_application.py", line 1115, in process_update
    await coroutine
  File "/Users/nikita/PycharmProjects/tg_bot_project/venv/lib/python3.10/site-packages/telegram/ext/_conversationhandler.py", line 826, in handle_update
    new_state: object = await handler.handle_update(
  File "/Users/nikita/PycharmProjects/tg_bot_project/venv/lib/python3.10/site-packages/telegram/ext/_handler.py", line 141, in handle_update
    return await self.callback(update, context)
  File "/Users/nikita/PycharmProjects/tg_bot_project/tg_bot_project/output/app.py", line 462, in weather_start
    await update.message.reply_text('РџСЂРёРІРµС‚. Р§С‚РѕР±С‹ СѓР·РЅР°С‚СЊ РёРЅС„РѕСЂРјР°С†РёСЋ Рѕ РїРѕРіРѕРґРµ, РІС‹Р±РµСЂРё, РєР°Рє С‚С‹ РїСЂРёС€Р»РµС€СЊ'
  File "/Users/nikita/PycharmProjects/tg_bot_project/venv/lib/python3.10/site-packages/telegram/_message.py", line 1041, in reply_text
    return await self.get_bot().send_message(
  File "/Users/nikita/PycharmProjects/tg_bot_project/venv/lib/python3.10/site-packages/telegram/ext/_extbot.py", line 2618, in send_message
    return await super().send_message(
  File "/Users/nikita/PycharmProjects/tg_bot_project/venv/lib/python3.10/site-packages/telegram/_bot.py", line 368, in decorator
    result = await func(*args, **kwargs)  # skipcq: PYL-E1102
  File "/Users/nikita/PycharmProjects/tg_bot_project/venv/lib/python3.10/site-packages/telegram/_bot.py", line 797, in send_message
    return await self._send_message(
  File "/Users/nikita/PycharmProjects/tg_bot_project/venv/lib/python3.10/site-packages/telegram/ext/_extbot.py", line 494, in _send_message
    result = await super()._send_message(
  File "/Users/nikita/PycharmProjects/tg_bot_project/venv/lib/python3.10/site-packages/telegram/_bot.py", line 549, in _send_message
    result = await self._post(
  File "/Users/nikita/PycharmProjects/tg_bot_project/venv/lib/python3.10/site-packages/telegram/_bot.py", line 456, in _post
    return await self._do_post(
  File "/Users/nikita/PycharmProjects/tg_bot_project/venv/lib/python3.10/site-packages/telegram/ext/_extbot.py", line 312, in _do_post
    return await super()._do_post(
  File "/Users/nikita/PycharmProjects/tg_bot_project/venv/lib/python3.10/site-packages/telegram/_bot.py", line 487, in _do_post
    return await request.post(
  File "/Users/nikita/PycharmProjects/tg_bot_project/venv/lib/python3.10/site-packages/telegram/request/_baserequest.py", line 165, in post
    result = await self._request_wrapper(
  File "/Users/nikita/PycharmProjects/tg_bot_project/venv/lib/python3.10/site-packages/telegram/request/_baserequest.py", line 290, in _request_wrapper
    raise NetworkError(f"Unknown error in HTTP implementation: {repr(exc)}") from exc
telegram.error.NetworkError: Unknown error in HTTP implementation: TypeError('Object of type coroutine is not JSON serializable')
2023-04-29 16:57:38,718 - telegram.ext._application - INFO - Application is stopping. This might take a moment.
2023-04-29 16:57:38,719 - telegram.ext._application - INFO - Application.stop() complete
2023-04-29 16:57:38,789 - asyncio - ERROR - Unclosed client session
client_session: <aiohttp.client.ClientSession object at 0x11e2820b0>
2023-04-29 16:57:39,932 - telegram.ext._application - INFO - Application started
2023-04-29 16:58:13,629 - telegram.ext._application - INFO - Application is stopping. This might take a moment.
2023-04-29 16:58:13,629 - telegram.ext._application - INFO - Application.stop() complete
2023-04-29 16:58:13,699 - asyncio - ERROR - Unclosed client session
client_session: <aiohttp.client.ClientSession object at 0x11fb821a0>
2023-04-29 16:58:16,649 - telegram.ext._application - INFO - Application started
2023-04-29 16:58:47,455 - telegram.ext._application - INFO - Application is stopping. This might take a moment.
2023-04-29 16:58:47,455 - telegram.ext._application - INFO - Application.stop() complete
2023-04-29 16:58:47,534 - asyncio - ERROR - Unclosed client session
client_session: <aiohttp.client.ClientSession object at 0x1311ed780>
2023-04-29 16:58:50,544 - telegram.ext._application - INFO - Application started
2023-04-29 18:31:26,109 - telegram.ext._application - INFO - Application is stopping. This might take a moment.
2023-04-29 18:31:26,112 - telegram.ext._application - INFO - Application.stop() complete
2023-04-29 18:31:26,192 - asyncio - ERROR - Unclosed client session
client_session: <aiohttp.client.ClientSession object at 0x1600863b0>
2023-04-29 18:31:27,666 - telegram.ext._application - INFO - Application started
2023-04-29 18:31:49,523 - telegram.ext._application - ERROR - No error handlers are registered, logging exception.
Traceback (most recent call last):
  File "/Users/nikita/PycharmProjects/tg_bot_project/venv/lib/python3.10/site-packages/telegram/ext/_application.py", line 1115, in process_update
    await coroutine
  File "/Users/nikita/PycharmProjects/tg_bot_project/venv/lib/python3.10/site-packages/telegram/ext/_conversationhandler.py", line 826, in handle_update
    new_state: object = await handler.handle_update(
  File "/Users/nikita/PycharmProjects/tg_bot_project/venv/lib/python3.10/site-packages/telegram/ext/_handler.py", line 141, in handle_update
    return await self.callback(update, context)
  File "/Users/nikita/PycharmProjects/tg_bot_project/tg_bot_project/output/app.py", line 160, in address_loc
    total_msg_func(update)
  File "/Users/nikita/PycharmProjects/tg_bot_project/tg_bot_project/output/funcs_backend.py", line 354, in total_msg_func
    user.total_len += len("".join(update.message.text.split()))
AttributeError: 'NoneType' object has no attribute 'split'
2023-04-29 18:31:57,459 - telegram.ext._application - ERROR - No error handlers are registered, logging exception.
Traceback (most recent call last):
  File "/Users/nikita/PycharmProjects/tg_bot_project/venv/lib/python3.10/site-packages/telegram/ext/_application.py", line 1115, in process_update
    await coroutine
  File "/Users/nikita/PycharmProjects/tg_bot_project/venv/lib/python3.10/site-packages/telegram/ext/_conversationhandler.py", line 826, in handle_update
    new_state: object = await handler.handle_update(
  File "/Users/nikita/PycharmProjects/tg_bot_project/venv/lib/python3.10/site-packages/telegram/ext/_handler.py", line 141, in handle_update
    return await self.callback(update, context)
  File "/Users/nikita/PycharmProjects/tg_bot_project/tg_bot_project/output/app.py", line 160, in address_loc
    total_msg_func(update)
  File "/Users/nikita/PycharmProjects/tg_bot_project/tg_bot_project/output/funcs_backend.py", line 354, in total_msg_func
    user.total_len += len("".join(update.message.text.split()))
AttributeError: 'NoneType' object has no attribute 'split'
2023-04-29 18:44:28,953 - telegram.ext._application - INFO - Application is stopping. This might take a moment.
2023-04-29 18:44:28,953 - telegram.ext._application - INFO - Application.stop() complete
2023-04-29 18:44:29,034 - asyncio - ERROR - Unclosed client session
client_session: <aiohttp.client.ClientSession object at 0x129910c70>
2023-04-29 18:44:30,411 - telegram.ext._application - INFO - Application started
2023-04-29 18:45:10,603 - telegram.ext._application - ERROR - No error handlers are registered, logging exception.
Traceback (most recent call last):
  File "/Users/nikita/PycharmProjects/tg_bot_project/venv/lib/python3.10/site-packages/telegram/ext/_application.py", line 1115, in process_update
    await coroutine
  File "/Users/nikita/PycharmProjects/tg_bot_project/venv/lib/python3.10/site-packages/telegram/ext/_conversationhandler.py", line 826, in handle_update
    new_state: object = await handler.handle_update(
  File "/Users/nikita/PycharmProjects/tg_bot_project/venv/lib/python3.10/site-packages/telegram/ext/_handler.py", line 141, in handle_update
    return await self.callback(update, context)
  File "/Users/nikita/PycharmProjects/tg_bot_project/tg_bot_project/output/app.py", line 277, in start_game
    await update.message.reply_text(f'Р”Р»СЏ РЅР°С‡Р°Р»Р° РІС‹Р№РґРё РёР· РїСЂРµРґС‹РґСѓС‰РµРіРѕ РґРёР°Р»РѕРіР°: {context.user_data["cmd"]}')
KeyError: 'cmd'
2023-04-29 18:45:17,159 - telegram.ext._application - ERROR - No error handlers are registered, logging exception.
Traceback (most recent call last):
  File "/Users/nikita/PycharmProjects/tg_bot_project/venv/lib/python3.10/site-packages/telegram/ext/_application.py", line 1115, in process_update
    await coroutine
  File "/Users/nikita/PycharmProjects/tg_bot_project/venv/lib/python3.10/site-packages/telegram/ext/_conversationhandler.py", line 826, in handle_update
    new_state: object = await handler.handle_update(
  File "/Users/nikita/PycharmProjects/tg_bot_project/venv/lib/python3.10/site-packages/telegram/ext/_handler.py", line 141, in handle_update
    return await self.callback(update, context)
  File "/Users/nikita/PycharmProjects/tg_bot_project/tg_bot_project/output/app.py", line 277, in start_game
    await update.message.reply_text(f'Р”Р»СЏ РЅР°С‡Р°Р»Р° РІС‹Р№РґРё РёР· РїСЂРµРґС‹РґСѓС‰РµРіРѕ РґРёР°Р»РѕРіР°: {context.user_data["cmd"]}')
KeyError: 'cmd'
2023-04-29 18:46:09,026 - telegram.ext._application - INFO - Application is stopping. This might take a moment.
2023-04-29 18:46:09,026 - telegram.ext._application - INFO - Application.stop() complete
2023-04-29 18:46:09,096 - asyncio - ERROR - Unclosed client session
client_session: <aiohttp.client.ClientSession object at 0x11db82920>
2023-04-29 18:46:10,253 - telegram.ext._application - INFO - Application started
2023-04-29 18:56:23,164 - matplotlib.category - INFO - Using categorical units to plot a list of strings that are all parsable as floats or dates. If these strings should be plotted as numbers, cast to the appropriate data type before plotting.
2023-04-29 18:56:23,165 - matplotlib.category - INFO - Using categorical units to plot a list of strings that are all parsable as floats or dates. If these strings should be plotted as numbers, cast to the appropriate data type before plotting.
2023-04-29 18:56:23,166 - matplotlib.category - INFO - Using categorical units to plot a list of strings that are all parsable as floats or dates. If these strings should be plotted as numbers, cast to the appropriate data type before plotting.
2023-04-29 19:37:16,152 - telegram.ext._application - INFO - Application is stopping. This might take a moment.
2023-04-29 19:37:16,152 - telegram.ext._application - INFO - Application.stop() complete
2023-04-29 19:37:16,223 - asyncio - ERROR - Unclosed client session
client_session: <aiohttp.client.ClientSession object at 0x12567edd0>
2023-04-29 19:37:17,509 - telegram.ext._application - INFO - Application started
2023-04-29 19:38:01,343 - telegram.ext._application - INFO - Application is stopping. This might take a moment.
2023-04-29 19:38:01,343 - telegram.ext._application - INFO - Application.stop() complete
2023-04-29 19:38:01,412 - asyncio - ERROR - Unclosed client session
client_session: <aiohttp.client.ClientSession object at 0x121c368f0>
2023-04-29 19:38:02,691 - telegram.ext._application - INFO - Application started
2023-04-29 19:42:39,316 - telegram.ext._application - INFO - Application is stopping. This might take a moment.
2023-04-29 19:42:39,316 - telegram.ext._application - INFO - Application.stop() complete
2023-04-29 19:42:39,395 - asyncio - ERROR - Unclosed client session
client_session: <aiohttp.client.ClientSession object at 0x12ef7ee00>
2023-04-29 19:42:40,654 - telegram.ext._application - INFO - Application started
2023-04-29 20:35:03,117 - telegram.ext._application - INFO - Application is stopping. This might take a moment.
2023-04-29 20:35:03,118 - telegram.ext._application - INFO - Application.stop() complete
2023-04-29 20:35:03,196 - asyncio - ERROR - Unclosed client session
client_session: <aiohttp.client.ClientSession object at 0x134782aa0>
2023-04-29 20:35:04,445 - telegram.ext._application - INFO - Application started
2023-04-29 20:37:42,743 - telegram.ext._application - INFO - Application is stopping. This might take a moment.
2023-04-29 20:37:42,743 - telegram.ext._application - INFO - Application.stop() complete
2023-04-29 20:37:42,812 - asyncio - ERROR - Unclosed client session
client_session: <aiohttp.client.ClientSession object at 0x128a73730>
2023-04-29 20:37:44,038 - telegram.ext._application - INFO - Application started
2023-04-29 20:40:05,639 - telegram.ext._application - INFO - Application is stopping. This might take a moment.
2023-04-29 20:40:05,640 - telegram.ext._application - INFO - Application.stop() complete
2023-04-29 20:40:05,710 - asyncio - ERROR - Unclosed client session
client_session: <aiohttp.client.ClientSession object at 0x12f211f30>
2023-04-29 20:40:07,114 - telegram.ext._application - INFO - Application started
2023-04-29 21:07:17,635 - telegram.ext._application - INFO - Application is stopping. This might take a moment.
2023-04-29 21:07:17,636 - telegram.ext._application - INFO - Application.stop() complete
2023-04-29 21:07:17,713 - asyncio - ERROR - Unclosed client session
client_session: <aiohttp.client.ClientSession object at 0x11f58da20>
2023-04-29 21:07:18,981 - telegram.ext._application - INFO - Application started
2023-04-29 21:08:09,880 - telegram.ext._application - INFO - Application is stopping. This might take a moment.
2023-04-29 21:08:09,880 - telegram.ext._application - INFO - Application.stop() complete
2023-04-29 21:08:09,949 - asyncio - ERROR - Unclosed client session
client_session: <aiohttp.client.ClientSession object at 0x123f73910>
2023-04-29 21:08:11,081 - telegram.ext._application - INFO - Application started
2023-04-29 21:08:36,074 - telegram.ext._application - INFO - Application is stopping. This might take a moment.
2023-04-29 21:08:36,074 - telegram.ext._application - INFO - Application.stop() complete
2023-04-29 21:08:36,142 - asyncio - ERROR - Unclosed client session
client_session: <aiohttp.client.ClientSession object at 0x11d589ed0>
2023-04-29 21:21:09,808 - telegram.ext._application - INFO - Application started
2023-04-29 21:22:58,532 - telegram.ext._application - INFO - Application is stopping. This might take a moment.
2023-04-29 21:22:58,532 - telegram.ext._application - INFO - Application.stop() complete
2023-04-29 21:22:58,601 - asyncio - ERROR - Unclosed client session
client_session: <aiohttp.client.ClientSession object at 0x133173f10>
2023-04-29 21:22:59,835 - telegram.ext._application - INFO - Application started
2023-04-29 21:23:00,665 - telegram.ext._application - INFO - Application is stopping. This might take a moment.
2023-04-29 21:23:00,665 - telegram.ext._application - INFO - Application.stop() complete
2023-04-29 21:23:00,734 - asyncio - ERROR - Unclosed client session
client_session: <aiohttp.client.ClientSession object at 0x11e54b9d0>
2023-04-29 21:23:03,504 - telegram.ext._application - INFO - Application started
2023-04-29 21:27:00,921 - telegram.ext._application - INFO - Application is stopping. This might take a moment.
2023-04-29 21:27:00,921 - telegram.ext._application - INFO - Application.stop() complete
2023-04-29 21:27:01,004 - asyncio - ERROR - Unclosed client session
client_session: <aiohttp.client.ClientSession object at 0x1422decb0>
2023-04-29 21:27:03,159 - telegram.ext._application - INFO - Application started
2023-04-29 21:27:25,941 - telegram.ext._application - INFO - Application is stopping. This might take a moment.
2023-04-29 21:27:25,941 - telegram.ext._application - INFO - Application.stop() complete
2023-04-29 21:27:46,009 - telegram.ext._application - INFO - Application started
2023-04-29 21:44:58,093 - telegram.ext._application - INFO - Application is stopping. This might take a moment.
2023-04-29 21:44:58,094 - telegram.ext._application - INFO - Application.stop() complete
2023-04-29 21:44:58,166 - asyncio - ERROR - Unclosed client session
client_session: <aiohttp.client.ClientSession object at 0x12e8fbd30>
2023-04-29 21:44:59,439 - telegram.ext._application - INFO - Application started
2023-04-29 21:53:32,674 - telegram.ext._application - INFO - Application is stopping. This might take a moment.
2023-04-29 21:53:32,677 - telegram.ext._application - INFO - Application.stop() complete
2023-04-29 21:53:32,757 - asyncio - ERROR - Unclosed client session
client_session: <aiohttp.client.ClientSession object at 0x1440a01f0>
2023-04-29 21:54:01,001 - telegram.ext._application - INFO - Application started
2023-04-29 21:55:23,786 - telegram.ext._application - INFO - Application is stopping. This might take a moment.
2023-04-29 21:55:23,786 - telegram.ext._application - INFO - Application.stop() complete
2023-04-29 21:55:23,859 - asyncio - ERROR - Unclosed client session
client_session: <aiohttp.client.ClientSession object at 0x139e2a860>
2023-04-29 22:01:29,124 - telegram.ext._application - INFO - Application started
2023-04-29 22:07:23,095 - telegram.ext._application - INFO - Application is stopping. This might take a moment.
2023-04-29 22:07:23,095 - telegram.ext._application - INFO - Application.stop() complete
2023-04-29 22:07:23,167 - asyncio - ERROR - Unclosed client session
client_session: <aiohttp.client.ClientSession object at 0x128b988b0>
2023-04-30 16:45:29,032 - telegram.ext._application - INFO - Application started
2023-04-30 18:23:42,871 - telegram.ext._application - INFO - Application started
2023-04-30 18:58:14,503 - telegram.ext._application - ERROR - No error handlers are registered, logging exception.
Traceback (most recent call last):
  File "/Users/nikita/PycharmProjects/tg_bot_project/venv/lib/python3.10/site-packages/telegram/ext/_application.py", line 1115, in process_update
    await coroutine
  File "/Users/nikita/PycharmProjects/tg_bot_project/venv/lib/python3.10/site-packages/telegram/ext/_conversationhandler.py", line 826, in handle_update
    new_state: object = await handler.handle_update(
  File "/Users/nikita/PycharmProjects/tg_bot_project/venv/lib/python3.10/site-packages/telegram/ext/_handler.py", line 141, in handle_update
    return await self.callback(update, context)
  File "/Users/nikita/PycharmProjects/tg_bot_project/tg_bot_project/output/server.py", line 599, in change_date
    await query.answer()
  File "/Users/nikita/PycharmProjects/tg_bot_project/venv/lib/python3.10/site-packages/telegram/_callbackquery.py", line 180, in answer
    return await self.get_bot().answer_callback_query(
  File "/Users/nikita/PycharmProjects/tg_bot_project/venv/lib/python3.10/site-packages/telegram/ext/_extbot.py", line 760, in answer_callback_query
    return await super().answer_callback_query(
  File "/Users/nikita/PycharmProjects/tg_bot_project/venv/lib/python3.10/site-packages/telegram/_bot.py", line 368, in decorator
    result = await func(*args, **kwargs)  # skipcq: PYL-E1102
  File "/Users/nikita/PycharmProjects/tg_bot_project/venv/lib/python3.10/site-packages/telegram/_bot.py", line 3266, in answer_callback_query
    result = await self._post(
  File "/Users/nikita/PycharmProjects/tg_bot_project/venv/lib/python3.10/site-packages/telegram/_bot.py", line 456, in _post
    return await self._do_post(
  File "/Users/nikita/PycharmProjects/tg_bot_project/venv/lib/python3.10/site-packages/telegram/ext/_extbot.py", line 312, in _do_post
    return await super()._do_post(
  File "/Users/nikita/PycharmProjects/tg_bot_project/venv/lib/python3.10/site-packages/telegram/_bot.py", line 487, in _do_post
    return await request.post(
  File "/Users/nikita/PycharmProjects/tg_bot_project/venv/lib/python3.10/site-packages/telegram/request/_baserequest.py", line 165, in post
    result = await self._request_wrapper(
  File "/Users/nikita/PycharmProjects/tg_bot_project/venv/lib/python3.10/site-packages/telegram/request/_baserequest.py", line 328, in _request_wrapper
    raise BadRequest(message)
telegram.error.BadRequest: Query is too old and response timeout expired or query id is invalid
2023-04-30 18:58:14,605 - telegram.ext._application - ERROR - No error handlers are registered, logging exception.
Traceback (most recent call last):
  File "/Users/nikita/PycharmProjects/tg_bot_project/venv/lib/python3.10/site-packages/telegram/ext/_application.py", line 1115, in process_update
    await coroutine
  File "/Users/nikita/PycharmProjects/tg_bot_project/venv/lib/python3.10/site-packages/telegram/ext/_conversationhandler.py", line 826, in handle_update
    new_state: object = await handler.handle_update(
  File "/Users/nikita/PycharmProjects/tg_bot_project/venv/lib/python3.10/site-packages/telegram/ext/_handler.py", line 141, in handle_update
    return await self.callback(update, context)
  File "/Users/nikita/PycharmProjects/tg_bot_project/tg_bot_project/output/server.py", line 599, in change_date
    await query.answer()
  File "/Users/nikita/PycharmProjects/tg_bot_project/venv/lib/python3.10/site-packages/telegram/_callbackquery.py", line 180, in answer
    return await self.get_bot().answer_callback_query(
  File "/Users/nikita/PycharmProjects/tg_bot_project/venv/lib/python3.10/site-packages/telegram/ext/_extbot.py", line 760, in answer_callback_query
    return await super().answer_callback_query(
  File "/Users/nikita/PycharmProjects/tg_bot_project/venv/lib/python3.10/site-packages/telegram/_bot.py", line 368, in decorator
    result = await func(*args, **kwargs)  # skipcq: PYL-E1102
  File "/Users/nikita/PycharmProjects/tg_bot_project/venv/lib/python3.10/site-packages/telegram/_bot.py", line 3266, in answer_callback_query
    result = await self._post(
  File "/Users/nikita/PycharmProjects/tg_bot_project/venv/lib/python3.10/site-packages/telegram/_bot.py", line 456, in _post
    return await self._do_post(
  File "/Users/nikita/PycharmProjects/tg_bot_project/venv/lib/python3.10/site-packages/telegram/ext/_extbot.py", line 312, in _do_post
    return await super()._do_post(
  File "/Users/nikita/PycharmProjects/tg_bot_project/venv/lib/python3.10/site-packages/telegram/_bot.py", line 487, in _do_post
    return await request.post(
  File "/Users/nikita/PycharmProjects/tg_bot_project/venv/lib/python3.10/site-packages/telegram/request/_baserequest.py", line 165, in post
    result = await self._request_wrapper(
  File "/Users/nikita/PycharmProjects/tg_bot_project/venv/lib/python3.10/site-packages/telegram/request/_baserequest.py", line 328, in _request_wrapper
    raise BadRequest(message)
telegram.error.BadRequest: Query is too old and response timeout expired or query id is invalid
2023-04-30 18:58:14,692 - telegram.ext._application - ERROR - No error handlers are registered, logging exception.
Traceback (most recent call last):
  File "/Users/nikita/PycharmProjects/tg_bot_project/venv/lib/python3.10/site-packages/telegram/ext/_application.py", line 1115, in process_update
    await coroutine
  File "/Users/nikita/PycharmProjects/tg_bot_project/venv/lib/python3.10/site-packages/telegram/ext/_conversationhandler.py", line 826, in handle_update
    new_state: object = await handler.handle_update(
  File "/Users/nikita/PycharmProjects/tg_bot_project/venv/lib/python3.10/site-packages/telegram/ext/_handler.py", line 141, in handle_update
    return await self.callback(update, context)
  File "/Users/nikita/PycharmProjects/tg_bot_project/tg_bot_project/output/server.py", line 599, in change_date
    await query.answer()
  File "/Users/nikita/PycharmProjects/tg_bot_project/venv/lib/python3.10/site-packages/telegram/_callbackquery.py", line 180, in answer
    return await self.get_bot().answer_callback_query(
  File "/Users/nikita/PycharmProjects/tg_bot_project/venv/lib/python3.10/site-packages/telegram/ext/_extbot.py", line 760, in answer_callback_query
    return await super().answer_callback_query(
  File "/Users/nikita/PycharmProjects/tg_bot_project/venv/lib/python3.10/site-packages/telegram/_bot.py", line 368, in decorator
    result = await func(*args, **kwargs)  # skipcq: PYL-E1102
  File "/Users/nikita/PycharmProjects/tg_bot_project/venv/lib/python3.10/site-packages/telegram/_bot.py", line 3266, in answer_callback_query
    result = await self._post(
  File "/Users/nikita/PycharmProjects/tg_bot_project/venv/lib/python3.10/site-packages/telegram/_bot.py", line 456, in _post
    return await self._do_post(
  File "/Users/nikita/PycharmProjects/tg_bot_project/venv/lib/python3.10/site-packages/telegram/ext/_extbot.py", line 312, in _do_post
    return await super()._do_post(
  File "/Users/nikita/PycharmProjects/tg_bot_project/venv/lib/python3.10/site-packages/telegram/_bot.py", line 487, in _do_post
    return await request.post(
  File "/Users/nikita/PycharmProjects/tg_bot_project/venv/lib/python3.10/site-packages/telegram/request/_baserequest.py", line 165, in post
    result = await self._request_wrapper(
  File "/Users/nikita/PycharmProjects/tg_bot_project/venv/lib/python3.10/site-packages/telegram/request/_baserequest.py", line 328, in _request_wrapper
    raise BadRequest(message)
telegram.error.BadRequest: Query is too old and response timeout expired or query id is invalid
2023-04-30 19:00:15,139 - asyncio - ERROR - Unclosed client session
client_session: <aiohttp.client.ClientSession object at 0x151938d00>
2023-04-30 19:00:15,140 - asyncio - ERROR - Unclosed connector
connections: ['[(<aiohttp.client_proto.ResponseHandler object at 0x1520f8ee0>, 936262.212281291)]']
connector: <aiohttp.connector.TCPConnector object at 0x151938d30>
2023-04-30 19:00:34,688 - asyncio - ERROR - Unclosed client session
client_session: <aiohttp.client.ClientSession object at 0x1523ceb60>
2023-04-30 19:00:34,688 - asyncio - ERROR - Unclosed connector
connections: ['[(<aiohttp.client_proto.ResponseHandler object at 0x1522bf1c0>, 936270.530017916)]']
connector: <aiohttp.connector.TCPConnector object at 0x152073910>
2023-04-30 19:04:31,585 - openai - INFO - error_code=invalid_api_key error_message='Incorrect API key provided: sk-3i619***************************************OiRT. You can find your API key at https://platform.openai.com/account/api-keys.' error_param=None error_type=invalid_request_error message='OpenAI API error received' stream_error=False
2023-04-30 19:04:31,586 - telegram.ext._application - ERROR - No error handlers are registered, logging exception.
Traceback (most recent call last):
  File "/Users/nikita/PycharmProjects/tg_bot_project/venv/lib/python3.10/site-packages/telegram/ext/_application.py", line 1115, in process_update
    await coroutine
  File "/Users/nikita/PycharmProjects/tg_bot_project/venv/lib/python3.10/site-packages/telegram/ext/_conversationhandler.py", line 826, in handle_update
    new_state: object = await handler.handle_update(
  File "/Users/nikita/PycharmProjects/tg_bot_project/venv/lib/python3.10/site-packages/telegram/ext/_handler.py", line 141, in handle_update
    return await self.callback(update, context)
  File "/Users/nikita/PycharmProjects/tg_bot_project/tg_bot_project/output/server.py", line 437, in text_request
    return await self.send_response(update, context, update.message.text, info_msg, chat)
  File "/Users/nikita/PycharmProjects/tg_bot_project/tg_bot_project/output/server.py", line 440, in send_response
    resp = get_answer(request)
  File "/Users/nikita/PycharmProjects/tg_bot_project/tg_bot_project/output/funcs_backend.py", line 295, in get_answer
    completion = openai.Completion.create(engine="text-davinci-003", prompt=prompt, temperature=0.7,
  File "/Users/nikita/PycharmProjects/tg_bot_project/venv/lib/python3.10/site-packages/openai/api_resources/completion.py", line 25, in create
    return super().create(*args, **kwargs)
  File "/Users/nikita/PycharmProjects/tg_bot_project/venv/lib/python3.10/site-packages/openai/api_resources/abstract/engine_api_resource.py", line 153, in create
    response, _, api_key = requestor.request(
  File "/Users/nikita/PycharmProjects/tg_bot_project/venv/lib/python3.10/site-packages/openai/api_requestor.py", line 226, in request
    resp, got_stream = self._interpret_response(result, stream)
  File "/Users/nikita/PycharmProjects/tg_bot_project/venv/lib/python3.10/site-packages/openai/api_requestor.py", line 620, in _interpret_response
    self._interpret_response_line(
  File "/Users/nikita/PycharmProjects/tg_bot_project/venv/lib/python3.10/site-packages/openai/api_requestor.py", line 683, in _interpret_response_line
    raise self.handle_error_response(
openai.error.AuthenticationError: Incorrect API key provided: sk-3i619***************************************OiRT. You can find your API key at https://platform.openai.com/account/api-keys.
2023-04-30 19:10:07,802 - telegram.ext._application - INFO - Application is stopping. This might take a moment.
2023-04-30 19:10:07,803 - telegram.ext._application - INFO - Application.stop() complete
2023-04-30 19:10:07,916 - asyncio - ERROR - Unclosed client session
client_session: <aiohttp.client.ClientSession object at 0x150e1d000>
2023-04-30 19:10:34,400 - telegram.ext._application - INFO - Application started
2023-05-01 15:05:56,932 - telegram.ext._application - INFO - Application started
2023-05-01 15:06:19,652 - openai - INFO - error_code=invalid_api_key error_message='Incorrect API key provided: sk-3i619***************************************OiRT. You can find your API key at https://platform.openai.com/account/api-keys.' error_param=None error_type=invalid_request_error message='OpenAI API error received' stream_error=False
2023-05-01 15:06:19,653 - telegram.ext._application - ERROR - No error handlers are registered, logging exception.
Traceback (most recent call last):
  File "/Users/nikita/PycharmProjects/tg_bot_project/venv/lib/python3.10/site-packages/telegram/ext/_application.py", line 1115, in process_update
    await coroutine
  File "/Users/nikita/PycharmProjects/tg_bot_project/venv/lib/python3.10/site-packages/telegram/ext/_conversationhandler.py", line 826, in handle_update
    new_state: object = await handler.handle_update(
  File "/Users/nikita/PycharmProjects/tg_bot_project/venv/lib/python3.10/site-packages/telegram/ext/_handler.py", line 141, in handle_update
    return await self.callback(update, context)
  File "/Users/nikita/PycharmProjects/tg_bot_project/tg_bot_project/output/server.py", line 437, in text_request
    return await self.send_response(update, context, update.message.text, info_msg, chat)
  File "/Users/nikita/PycharmProjects/tg_bot_project/tg_bot_project/output/server.py", line 440, in send_response
    resp = get_answer(request)
  File "/Users/nikita/PycharmProjects/tg_bot_project/tg_bot_project/output/funcs_backend.py", line 295, in get_answer
    completion = openai.Completion.create(engine="text-davinci-003", prompt=prompt, temperature=0.7,
  File "/Users/nikita/PycharmProjects/tg_bot_project/venv/lib/python3.10/site-packages/openai/api_resources/completion.py", line 25, in create
    return super().create(*args, **kwargs)
  File "/Users/nikita/PycharmProjects/tg_bot_project/venv/lib/python3.10/site-packages/openai/api_resources/abstract/engine_api_resource.py", line 153, in create
    response, _, api_key = requestor.request(
  File "/Users/nikita/PycharmProjects/tg_bot_project/venv/lib/python3.10/site-packages/openai/api_requestor.py", line 226, in request
    resp, got_stream = self._interpret_response(result, stream)
  File "/Users/nikita/PycharmProjects/tg_bot_project/venv/lib/python3.10/site-packages/openai/api_requestor.py", line 620, in _interpret_response
    self._interpret_response_line(
  File "/Users/nikita/PycharmProjects/tg_bot_project/venv/lib/python3.10/site-packages/openai/api_requestor.py", line 683, in _interpret_response_line
    raise self.handle_error_response(
openai.error.AuthenticationError: Incorrect API key provided: sk-3i619***************************************OiRT. You can find your API key at https://platform.openai.com/account/api-keys.
2023-05-01 15:19:33,508 - telegram.ext._application - INFO - Application is stopping. This might take a moment.
2023-05-01 15:19:33,516 - telegram.ext._application - INFO - Application.stop() complete
2023-05-01 15:19:33,600 - asyncio - ERROR - Unclosed client session
client_session: <aiohttp.client.ClientSession object at 0x133194eb0>
2023-05-01 15:19:34,853 - telegram.ext._application - INFO - Application started
2023-05-01 15:19:52,193 - openai - INFO - error_code=None error_message='You exceeded your current quota, please check your plan and billing details.' error_param=None error_type=insufficient_quota message='OpenAI API error received' stream_error=False
2023-05-01 15:19:52,193 - telegram.ext._application - ERROR - No error handlers are registered, logging exception.
Traceback (most recent call last):
  File "/Users/nikita/PycharmProjects/tg_bot_project/venv/lib/python3.10/site-packages/telegram/ext/_application.py", line 1115, in process_update
    await coroutine
  File "/Users/nikita/PycharmProjects/tg_bot_project/venv/lib/python3.10/site-packages/telegram/ext/_conversationhandler.py", line 826, in handle_update
    new_state: object = await handler.handle_update(
  File "/Users/nikita/PycharmProjects/tg_bot_project/venv/lib/python3.10/site-packages/telegram/ext/_handler.py", line 141, in handle_update
    return await self.callback(update, context)
  File "/Users/nikita/PycharmProjects/tg_bot_project/tg_bot_project/output/server.py", line 437, in text_request
    return await self.send_response(update, context, update.message.text, info_msg, chat)
  File "/Users/nikita/PycharmProjects/tg_bot_project/tg_bot_project/output/server.py", line 440, in send_response
    resp = get_answer(request)
  File "/Users/nikita/PycharmProjects/tg_bot_project/tg_bot_project/output/funcs_backend.py", line 295, in get_answer
    completion = openai.Completion.create(engine="text-davinci-003", prompt=prompt, temperature=0.7,
  File "/Users/nikita/PycharmProjects/tg_bot_project/venv/lib/python3.10/site-packages/openai/api_resources/completion.py", line 25, in create
    return super().create(*args, **kwargs)
  File "/Users/nikita/PycharmProjects/tg_bot_project/venv/lib/python3.10/site-packages/openai/api_resources/abstract/engine_api_resource.py", line 153, in create
    response, _, api_key = requestor.request(
  File "/Users/nikita/PycharmProjects/tg_bot_project/venv/lib/python3.10/site-packages/openai/api_requestor.py", line 226, in request
    resp, got_stream = self._interpret_response(result, stream)
  File "/Users/nikita/PycharmProjects/tg_bot_project/venv/lib/python3.10/site-packages/openai/api_requestor.py", line 620, in _interpret_response
    self._interpret_response_line(
  File "/Users/nikita/PycharmProjects/tg_bot_project/venv/lib/python3.10/site-packages/openai/api_requestor.py", line 683, in _interpret_response_line
    raise self.handle_error_response(
openai.error.RateLimitError: You exceeded your current quota, please check your plan and billing details.
2023-05-01 15:21:24,644 - telegram.ext._application - INFO - Application is stopping. This might take a moment.
2023-05-01 15:21:24,644 - telegram.ext._application - INFO - Application.stop() complete
2023-05-01 15:21:24,714 - asyncio - ERROR - Unclosed client session
client_session: <aiohttp.client.ClientSession object at 0x150e91120>
2023-05-01 15:21:25,960 - telegram.ext._application - INFO - Application started
2023-05-01 15:21:42,765 - openai - INFO - error_code=None error_message='You exceeded your current quota, please check your plan and billing details.' error_param=None error_type=insufficient_quota message='OpenAI API error received' stream_error=False
2023-05-01 15:21:42,765 - telegram.ext._application - ERROR - No error handlers are registered, logging exception.
Traceback (most recent call last):
  File "/Users/nikita/PycharmProjects/tg_bot_project/venv/lib/python3.10/site-packages/telegram/ext/_application.py", line 1115, in process_update
    await coroutine
  File "/Users/nikita/PycharmProjects/tg_bot_project/venv/lib/python3.10/site-packages/telegram/ext/_conversationhandler.py", line 826, in handle_update
    new_state: object = await handler.handle_update(
  File "/Users/nikita/PycharmProjects/tg_bot_project/venv/lib/python3.10/site-packages/telegram/ext/_handler.py", line 141, in handle_update
    return await self.callback(update, context)
  File "/Users/nikita/PycharmProjects/tg_bot_project/tg_bot_project/output/server.py", line 437, in text_request
    return await self.send_response(update, context, update.message.text, info_msg, chat)
  File "/Users/nikita/PycharmProjects/tg_bot_project/tg_bot_project/output/server.py", line 440, in send_response
    resp = get_answer(request)
  File "/Users/nikita/PycharmProjects/tg_bot_project/tg_bot_project/output/funcs_backend.py", line 295, in get_answer
    completion = openai.Completion.create(engine="text-davinci-003", prompt=prompt, temperature=0.7,
  File "/Users/nikita/PycharmProjects/tg_bot_project/venv/lib/python3.10/site-packages/openai/api_resources/completion.py", line 25, in create
    return super().create(*args, **kwargs)
  File "/Users/nikita/PycharmProjects/tg_bot_project/venv/lib/python3.10/site-packages/openai/api_resources/abstract/engine_api_resource.py", line 153, in create
    response, _, api_key = requestor.request(
  File "/Users/nikita/PycharmProjects/tg_bot_project/venv/lib/python3.10/site-packages/openai/api_requestor.py", line 226, in request
    resp, got_stream = self._interpret_response(result, stream)
  File "/Users/nikita/PycharmProjects/tg_bot_project/venv/lib/python3.10/site-packages/openai/api_requestor.py", line 620, in _interpret_response
    self._interpret_response_line(
  File "/Users/nikita/PycharmProjects/tg_bot_project/venv/lib/python3.10/site-packages/openai/api_requestor.py", line 683, in _interpret_response_line
    raise self.handle_error_response(
openai.error.RateLimitError: You exceeded your current quota, please check your plan and billing details.
2023-05-01 15:22:11,813 - telegram.ext._application - INFO - Application is stopping. This might take a moment.
2023-05-01 15:22:11,814 - telegram.ext._application - INFO - Application.stop() complete
2023-05-01 15:22:11,888 - asyncio - ERROR - Unclosed client session
client_session: <aiohttp.client.ClientSession object at 0x12d695000>
2023-05-01 15:22:12,965 - telegram.ext._application - INFO - Application started
2023-05-01 15:22:24,718 - openai - INFO - error_code=None error_message='You exceeded your current quota, please check your plan and billing details.' error_param=None error_type=insufficient_quota message='OpenAI API error received' stream_error=False
2023-05-01 15:22:24,719 - telegram.ext._application - ERROR - No error handlers are registered, logging exception.
Traceback (most recent call last):
  File "/Users/nikita/PycharmProjects/tg_bot_project/venv/lib/python3.10/site-packages/telegram/ext/_application.py", line 1115, in process_update
    await coroutine
  File "/Users/nikita/PycharmProjects/tg_bot_project/venv/lib/python3.10/site-packages/telegram/ext/_conversationhandler.py", line 826, in handle_update
    new_state: object = await handler.handle_update(
  File "/Users/nikita/PycharmProjects/tg_bot_project/venv/lib/python3.10/site-packages/telegram/ext/_handler.py", line 141, in handle_update
    return await self.callback(update, context)
  File "/Users/nikita/PycharmProjects/tg_bot_project/tg_bot_project/output/server.py", line 437, in text_request
    return await self.send_response(update, context, update.message.text, info_msg, chat)
  File "/Users/nikita/PycharmProjects/tg_bot_project/tg_bot_project/output/server.py", line 440, in send_response
    resp = get_answer(request)
  File "/Users/nikita/PycharmProjects/tg_bot_project/tg_bot_project/output/funcs_backend.py", line 295, in get_answer
    completion = openai.Completion.create(engine="text-davinci-003", prompt=prompt, temperature=0.7,
  File "/Users/nikita/PycharmProjects/tg_bot_project/venv/lib/python3.10/site-packages/openai/api_resources/completion.py", line 25, in create
    return super().create(*args, **kwargs)
  File "/Users/nikita/PycharmProjects/tg_bot_project/venv/lib/python3.10/site-packages/openai/api_resources/abstract/engine_api_resource.py", line 153, in create
    response, _, api_key = requestor.request(
  File "/Users/nikita/PycharmProjects/tg_bot_project/venv/lib/python3.10/site-packages/openai/api_requestor.py", line 226, in request
    resp, got_stream = self._interpret_response(result, stream)
  File "/Users/nikita/PycharmProjects/tg_bot_project/venv/lib/python3.10/site-packages/openai/api_requestor.py", line 620, in _interpret_response
    self._interpret_response_line(
  File "/Users/nikita/PycharmProjects/tg_bot_project/venv/lib/python3.10/site-packages/openai/api_requestor.py", line 683, in _interpret_response_line
    raise self.handle_error_response(
openai.error.RateLimitError: You exceeded your current quota, please check your plan and billing details.
2023-05-01 15:51:54,247 - telegram.ext._application - INFO - Application is stopping. This might take a moment.
2023-05-01 15:51:54,247 - telegram.ext._application - INFO - Application.stop() complete
2023-05-01 15:51:54,322 - asyncio - ERROR - Unclosed client session
client_session: <aiohttp.client.ClientSession object at 0x11cf910f0>
2023-05-01 15:51:55,453 - telegram.ext._application - INFO - Application started
2023-05-01 16:25:54,671 - asyncio - ERROR - Unclosed client session
client_session: <aiohttp.client.ClientSession object at 0x11fa98b20>
2023-05-01 16:25:54,672 - asyncio - ERROR - Unclosed connector
connections: ['[(<aiohttp.client_proto.ResponseHandler object at 0x11fae7e80>, 967515.645154958)]']
connector: <aiohttp.connector.TCPConnector object at 0x11dac1060>
2023-05-01 16:26:05,215 - asyncio - ERROR - Unclosed client session
client_session: <aiohttp.client.ClientSession object at 0x11fc26530>
2023-05-01 16:26:05,215 - asyncio - ERROR - Unclosed connector
connections: ['[(<aiohttp.client_proto.ResponseHandler object at 0x11fae41c0>, 967526.187493541)]']
connector: <aiohttp.connector.TCPConnector object at 0x11dac0970>
2023-05-01 16:27:06,911 - telegram.ext._application - INFO - Application is stopping. This might take a moment.
2023-05-01 16:27:06,911 - telegram.ext._application - INFO - Application.stop() complete
2023-05-01 16:27:06,984 - asyncio - ERROR - Unclosed client session
client_session: <aiohttp.client.ClientSession object at 0x11bf95000>
2023-05-01 16:27:08,391 - telegram.ext._application - INFO - Application started
2023-05-01 16:27:20,806 - asyncio - ERROR - Unclosed client session
client_session: <aiohttp.client.ClientSession object at 0x1374f8ee0>
2023-05-01 16:27:20,807 - asyncio - ERROR - Unclosed connector
connections: ['[(<aiohttp.client_proto.ResponseHandler object at 0x13728f700>, 967601.791037333)]']
connector: <aiohttp.connector.TCPConnector object at 0x1372afb20>
2023-05-01 16:28:41,232 - matplotlib.category - INFO - Using categorical units to plot a list of strings that are all parsable as floats or dates. If these strings should be plotted as numbers, cast to the appropriate data type before plotting.
2023-05-01 16:28:41,233 - matplotlib.category - INFO - Using categorical units to plot a list of strings that are all parsable as floats or dates. If these strings should be plotted as numbers, cast to the appropriate data type before plotting.
2023-05-01 16:28:41,235 - matplotlib.category - INFO - Using categorical units to plot a list of strings that are all parsable as floats or dates. If these strings should be plotted as numbers, cast to the appropriate data type before plotting.
