2023-04-29 03:21:52,799 - telegram.ext._application - INFO - Application started
2023-04-29 03:22:28,055 - telegram.ext._application - INFO - Application is stopping. This might take a moment.
2023-04-29 03:22:28,055 - telegram.ext._application - INFO - Application.stop() complete
2023-04-29 03:22:49,931 - telegram.ext._application - INFO - Application started
2023-04-29 03:22:59,823 - telegram.ext._application - ERROR - No error handlers are registered, logging exception.
Traceback (most recent call last):
  File "C:\Users\matve\Desktop\tg_bot_project\venv\lib\site-packages\telegram\ext\_application.py", line 1115, in process_update
    await coroutine
  File "C:\Users\matve\Desktop\tg_bot_project\venv\lib\site-packages\telegram\ext\_conversationhandler.py", line 826, in handle_update
    new_state: object = await handler.handle_update(
  File "C:\Users\matve\Desktop\tg_bot_project\venv\lib\site-packages\telegram\ext\_handler.py", line 141, in handle_update
    return await self.callback(update, context)
  File "C:\Users\matve\Desktop\tg_bot_project\output\app.py", line 475, in change_date
    text, for_robot = await get_weather(self.response, self.name_from, date=int(num) - 3)
  File "C:\Users\matve\Desktop\tg_bot_project\output\funcs_backend.py", line 251, in get_weather
    text += f"Ощущаемая температура °C: \U0001f321{now['feels_like']}\n"
KeyError: 'feels_like'
2023-04-29 03:23:02,128 - telegram.ext._application - ERROR - No error handlers are registered, logging exception.
Traceback (most recent call last):
  File "C:\Users\matve\Desktop\tg_bot_project\venv\lib\site-packages\telegram\ext\_application.py", line 1115, in process_update
    await coroutine
  File "C:\Users\matve\Desktop\tg_bot_project\venv\lib\site-packages\telegram\ext\_conversationhandler.py", line 826, in handle_update
    new_state: object = await handler.handle_update(
  File "C:\Users\matve\Desktop\tg_bot_project\venv\lib\site-packages\telegram\ext\_handler.py", line 141, in handle_update
    return await self.callback(update, context)
  File "C:\Users\matve\Desktop\tg_bot_project\output\app.py", line 475, in change_date
    text, for_robot = await get_weather(self.response, self.name_from, date=int(num) - 3)
  File "C:\Users\matve\Desktop\tg_bot_project\output\funcs_backend.py", line 251, in get_weather
    text += f"Ощущаемая температура °C: \U0001f321{now['feels_like']}\n"
KeyError: 'feels_like'
2023-04-29 03:23:49,442 - telegram.ext._application - ERROR - No error handlers are registered, logging exception.
Traceback (most recent call last):
  File "C:\Users\matve\Desktop\tg_bot_project\venv\lib\site-packages\telegram\ext\_application.py", line 1115, in process_update
    await coroutine
  File "C:\Users\matve\Desktop\tg_bot_project\venv\lib\site-packages\telegram\ext\_conversationhandler.py", line 826, in handle_update
    new_state: object = await handler.handle_update(
  File "C:\Users\matve\Desktop\tg_bot_project\venv\lib\site-packages\telegram\ext\_handler.py", line 141, in handle_update
    return await self.callback(update, context)
  File "C:\Users\matve\Desktop\tg_bot_project\output\app.py", line 475, in change_date
    text, for_robot = await get_weather(self.response, self.name_from, date=int(num) - 3)
  File "C:\Users\matve\Desktop\tg_bot_project\output\funcs_backend.py", line 251, in get_weather
    text += f"Ощущаемая температура °C: \U0001f321{now['feels_like']}\n"
KeyError: 'feels_like'
2023-04-29 03:23:52,832 - telegram.ext._application - ERROR - No error handlers are registered, logging exception.
Traceback (most recent call last):
  File "C:\Users\matve\Desktop\tg_bot_project\venv\lib\site-packages\telegram\ext\_application.py", line 1115, in process_update
    await coroutine
  File "C:\Users\matve\Desktop\tg_bot_project\venv\lib\site-packages\telegram\ext\_conversationhandler.py", line 826, in handle_update
    new_state: object = await handler.handle_update(
  File "C:\Users\matve\Desktop\tg_bot_project\venv\lib\site-packages\telegram\ext\_handler.py", line 141, in handle_update
    return await self.callback(update, context)
  File "C:\Users\matve\Desktop\tg_bot_project\output\app.py", line 475, in change_date
    text, for_robot = await get_weather(self.response, self.name_from, date=int(num) - 3)
  File "C:\Users\matve\Desktop\tg_bot_project\output\funcs_backend.py", line 251, in get_weather
    text += f"Ощущаемая температура °C: \U0001f321{now['feels_like']}\n"
KeyError: 'feels_like'
2023-04-29 03:23:53,673 - telegram.ext._application - ERROR - No error handlers are registered, logging exception.
Traceback (most recent call last):
  File "C:\Users\matve\Desktop\tg_bot_project\venv\lib\site-packages\telegram\ext\_application.py", line 1115, in process_update
    await coroutine
  File "C:\Users\matve\Desktop\tg_bot_project\venv\lib\site-packages\telegram\ext\_conversationhandler.py", line 826, in handle_update
    new_state: object = await handler.handle_update(
  File "C:\Users\matve\Desktop\tg_bot_project\venv\lib\site-packages\telegram\ext\_handler.py", line 141, in handle_update
    return await self.callback(update, context)
  File "C:\Users\matve\Desktop\tg_bot_project\output\app.py", line 475, in change_date
    text, for_robot = await get_weather(self.response, self.name_from, date=int(num) - 3)
  File "C:\Users\matve\Desktop\tg_bot_project\output\funcs_backend.py", line 251, in get_weather
    text += f"Ощущаемая температура °C: \U0001f321{now['feels_like']}\n"
KeyError: 'feels_like'
2023-04-29 03:23:54,454 - telegram.ext._application - ERROR - No error handlers are registered, logging exception.
Traceback (most recent call last):
  File "C:\Users\matve\Desktop\tg_bot_project\venv\lib\site-packages\telegram\ext\_application.py", line 1115, in process_update
    await coroutine
  File "C:\Users\matve\Desktop\tg_bot_project\venv\lib\site-packages\telegram\ext\_conversationhandler.py", line 826, in handle_update
    new_state: object = await handler.handle_update(
  File "C:\Users\matve\Desktop\tg_bot_project\venv\lib\site-packages\telegram\ext\_handler.py", line 141, in handle_update
    return await self.callback(update, context)
  File "C:\Users\matve\Desktop\tg_bot_project\output\app.py", line 475, in change_date
    text, for_robot = await get_weather(self.response, self.name_from, date=int(num) - 3)
  File "C:\Users\matve\Desktop\tg_bot_project\output\funcs_backend.py", line 251, in get_weather
    text += f"Ощущаемая температура °C: \U0001f321{now['feels_like']}\n"
KeyError: 'feels_like'
2023-04-29 03:23:55,054 - telegram.ext._application - ERROR - No error handlers are registered, logging exception.
Traceback (most recent call last):
  File "C:\Users\matve\Desktop\tg_bot_project\venv\lib\site-packages\telegram\ext\_application.py", line 1115, in process_update
    await coroutine
  File "C:\Users\matve\Desktop\tg_bot_project\venv\lib\site-packages\telegram\ext\_conversationhandler.py", line 826, in handle_update
    new_state: object = await handler.handle_update(
  File "C:\Users\matve\Desktop\tg_bot_project\venv\lib\site-packages\telegram\ext\_handler.py", line 141, in handle_update
    return await self.callback(update, context)
  File "C:\Users\matve\Desktop\tg_bot_project\output\app.py", line 475, in change_date
    text, for_robot = await get_weather(self.response, self.name_from, date=int(num) - 3)
  File "C:\Users\matve\Desktop\tg_bot_project\output\funcs_backend.py", line 251, in get_weather
    text += f"Ощущаемая температура °C: \U0001f321{now['feels_like']}\n"
KeyError: 'feels_like'
2023-04-29 03:23:55,479 - telegram.ext._application - ERROR - No error handlers are registered, logging exception.
Traceback (most recent call last):
  File "C:\Users\matve\Desktop\tg_bot_project\venv\lib\site-packages\telegram\ext\_application.py", line 1115, in process_update
    await coroutine
  File "C:\Users\matve\Desktop\tg_bot_project\venv\lib\site-packages\telegram\ext\_conversationhandler.py", line 826, in handle_update
    new_state: object = await handler.handle_update(
  File "C:\Users\matve\Desktop\tg_bot_project\venv\lib\site-packages\telegram\ext\_handler.py", line 141, in handle_update
    return await self.callback(update, context)
  File "C:\Users\matve\Desktop\tg_bot_project\output\app.py", line 475, in change_date
    text, for_robot = await get_weather(self.response, self.name_from, date=int(num) - 3)
  File "C:\Users\matve\Desktop\tg_bot_project\output\funcs_backend.py", line 251, in get_weather
    text += f"Ощущаемая температура °C: \U0001f321{now['feels_like']}\n"
KeyError: 'feels_like'
2023-04-29 03:24:17,568 - telegram.ext._application - INFO - Application is stopping. This might take a moment.
2023-04-29 03:24:17,569 - telegram.ext._application - INFO - Application.stop() complete
2023-04-29 03:24:22,312 - telegram.ext._application - INFO - Application started
2023-04-29 03:24:42,273 - telegram.ext._application - ERROR - No error handlers are registered, logging exception.
Traceback (most recent call last):
  File "C:\Users\matve\Desktop\tg_bot_project\venv\lib\site-packages\telegram\ext\_application.py", line 1115, in process_update
    await coroutine
  File "C:\Users\matve\Desktop\tg_bot_project\venv\lib\site-packages\telegram\ext\_conversationhandler.py", line 826, in handle_update
    new_state: object = await handler.handle_update(
  File "C:\Users\matve\Desktop\tg_bot_project\venv\lib\site-packages\telegram\ext\_handler.py", line 141, in handle_update
    return await self.callback(update, context)
  File "C:\Users\matve\Desktop\tg_bot_project\output\app.py", line 475, in change_date
    text, for_robot = await get_weather(self.response, self.name_from, date=int(num) - 3)
  File "C:\Users\matve\Desktop\tg_bot_project\output\funcs_backend.py", line 250, in get_weather
    now = response["forecasts"][date]["day"]
KeyError: 'day'
2023-04-29 03:24:44,082 - telegram.ext._application - ERROR - No error handlers are registered, logging exception.
Traceback (most recent call last):
  File "C:\Users\matve\Desktop\tg_bot_project\venv\lib\site-packages\telegram\ext\_application.py", line 1115, in process_update
    await coroutine
  File "C:\Users\matve\Desktop\tg_bot_project\venv\lib\site-packages\telegram\ext\_conversationhandler.py", line 826, in handle_update
    new_state: object = await handler.handle_update(
  File "C:\Users\matve\Desktop\tg_bot_project\venv\lib\site-packages\telegram\ext\_handler.py", line 141, in handle_update
    return await self.callback(update, context)
  File "C:\Users\matve\Desktop\tg_bot_project\output\app.py", line 475, in change_date
    text, for_robot = await get_weather(self.response, self.name_from, date=int(num) - 3)
  File "C:\Users\matve\Desktop\tg_bot_project\output\funcs_backend.py", line 250, in get_weather
    now = response["forecasts"][date]["day"]
KeyError: 'day'
2023-04-29 03:25:22,197 - telegram.ext._application - INFO - Application is stopping. This might take a moment.
2023-04-29 03:25:22,198 - telegram.ext._application - INFO - Application.stop() complete
2023-04-29 03:25:26,977 - telegram.ext._application - INFO - Application started
2023-04-29 03:25:36,676 - telegram.ext._application - ERROR - No error handlers are registered, logging exception.
Traceback (most recent call last):
  File "C:\Users\matve\Desktop\tg_bot_project\venv\lib\site-packages\telegram\ext\_application.py", line 1115, in process_update
    await coroutine
  File "C:\Users\matve\Desktop\tg_bot_project\venv\lib\site-packages\telegram\ext\_conversationhandler.py", line 826, in handle_update
    new_state: object = await handler.handle_update(
  File "C:\Users\matve\Desktop\tg_bot_project\venv\lib\site-packages\telegram\ext\_handler.py", line 141, in handle_update
    return await self.callback(update, context)
  File "C:\Users\matve\Desktop\tg_bot_project\output\app.py", line 475, in change_date
    text, for_robot = await get_weather(self.response, self.name_from, date=int(num) - 3)
  File "C:\Users\matve\Desktop\tg_bot_project\output\funcs_backend.py", line 250, in get_weather
    now = response["forecasts"][0]["day"]
KeyError: 'day'
2023-04-29 03:25:41,292 - telegram.ext._application - ERROR - No error handlers are registered, logging exception.
Traceback (most recent call last):
  File "C:\Users\matve\Desktop\tg_bot_project\venv\lib\site-packages\telegram\ext\_application.py", line 1115, in process_update
    await coroutine
  File "C:\Users\matve\Desktop\tg_bot_project\venv\lib\site-packages\telegram\ext\_conversationhandler.py", line 826, in handle_update
    new_state: object = await handler.handle_update(
  File "C:\Users\matve\Desktop\tg_bot_project\venv\lib\site-packages\telegram\ext\_handler.py", line 141, in handle_update
    return await self.callback(update, context)
  File "C:\Users\matve\Desktop\tg_bot_project\output\app.py", line 475, in change_date
    text, for_robot = await get_weather(self.response, self.name_from, date=int(num) - 3)
  File "C:\Users\matve\Desktop\tg_bot_project\output\funcs_backend.py", line 250, in get_weather
    now = response["forecasts"][0]["day"]
KeyError: 'day'
2023-04-29 03:25:42,852 - telegram.ext._application - ERROR - No error handlers are registered, logging exception.
Traceback (most recent call last):
  File "C:\Users\matve\Desktop\tg_bot_project\venv\lib\site-packages\telegram\ext\_application.py", line 1115, in process_update
    await coroutine
  File "C:\Users\matve\Desktop\tg_bot_project\venv\lib\site-packages\telegram\ext\_conversationhandler.py", line 826, in handle_update
    new_state: object = await handler.handle_update(
  File "C:\Users\matve\Desktop\tg_bot_project\venv\lib\site-packages\telegram\ext\_handler.py", line 141, in handle_update
    return await self.callback(update, context)
  File "C:\Users\matve\Desktop\tg_bot_project\output\app.py", line 475, in change_date
    text, for_robot = await get_weather(self.response, self.name_from, date=int(num) - 3)
  File "C:\Users\matve\Desktop\tg_bot_project\output\funcs_backend.py", line 250, in get_weather
    now = response["forecasts"][0]["day"]
KeyError: 'day'
2023-04-29 03:27:08,546 - telegram.ext._application - INFO - Application is stopping. This might take a moment.
2023-04-29 03:27:08,547 - telegram.ext._application - INFO - Application.stop() complete
2023-04-29 03:27:12,742 - telegram.ext._application - INFO - Application started
2023-04-29 03:28:13,620 - asyncio - ERROR - Unclosed client session
client_session: <aiohttp.client.ClientSession object at 0x000001FFCEBA87C0>
2023-04-29 03:28:13,620 - asyncio - ERROR - Unclosed connector
connections: ['[(<aiohttp.client_proto.ResponseHandler object at 0x000001FFCEAEE340>, 1261332.531)]']
connector: <aiohttp.connector.TCPConnector object at 0x000001FFCEBA8A00>
2023-04-29 03:28:41,674 - asyncio - ERROR - Unclosed client session
client_session: <aiohttp.client.ClientSession object at 0x000001FFCECC0DC0>
2023-04-29 03:28:41,674 - asyncio - ERROR - Unclosed connector
connections: ['[(<aiohttp.client_proto.ResponseHandler object at 0x000001FFCECC2400>, 1261360.656)]']
connector: <aiohttp.connector.TCPConnector object at 0x000001FFCECA8A90>
2023-04-29 03:28:48,868 - asyncio - ERROR - Unclosed client session
client_session: <aiohttp.client.ClientSession object at 0x000001FFCEDC5430>
2023-04-29 03:28:48,868 - asyncio - ERROR - Unclosed connector
connections: ['[(<aiohttp.client_proto.ResponseHandler object at 0x000001FFCECC2E20>, 1261367.843)]']
connector: <aiohttp.connector.TCPConnector object at 0x000001FFCECC10D0>
2023-04-29 03:28:52,563 - asyncio - ERROR - Unclosed client session
client_session: <aiohttp.client.ClientSession object at 0x000001FFCED56940>
2023-04-29 03:28:52,564 - asyncio - ERROR - Unclosed connector
connections: ['[(<aiohttp.client_proto.ResponseHandler object at 0x000001FFCEBAB5E0>, 1261371.531)]']
connector: <aiohttp.connector.TCPConnector object at 0x000001FFCECC00D0>
2023-04-29 03:31:49,168 - telegram.ext._application - INFO - Application is stopping. This might take a moment.
2023-04-29 03:31:49,169 - telegram.ext._application - INFO - Application.stop() complete
2023-04-29 03:58:09,482 - asyncio - ERROR - Unclosed client session
client_session: <aiohttp.client.ClientSession object at 0x11ff31ba0>
2023-04-29 03:58:14,531 - telegram.ext._application - INFO - Application started
2023-04-29 03:58:53,668 - telegram.ext._application - INFO - Application is stopping. This might take a moment.
2023-04-29 03:58:53,668 - telegram.ext._application - INFO - Application.stop() complete
2023-04-29 03:58:53,741 - asyncio - ERROR - Unclosed client session
client_session: <aiohttp.client.ClientSession object at 0x12756f7f0>
2023-04-29 03:58:54,943 - telegram.ext._application - INFO - Application started
2023-04-29 03:59:36,828 - asyncio - ERROR - Unclosed client session
client_session: <aiohttp.client.ClientSession object at 0x125a18190>
2023-04-29 03:59:36,830 - asyncio - ERROR - Unclosed connector
connections: ['[(<aiohttp.client_proto.ResponseHandler object at 0x125a0b520>, 886557.786815666)]']
connector: <aiohttp.connector.TCPConnector object at 0x12579ea40>
2023-04-29 03:59:42,681 - asyncio - ERROR - Unclosed client session
client_session: <aiohttp.client.ClientSession object at 0x1258053f0>
2023-04-29 03:59:42,682 - asyncio - ERROR - Unclosed connector
connections: ['[(<aiohttp.client_proto.ResponseHandler object at 0x12576dd20>, 886563.640229791)]']
connector: <aiohttp.connector.TCPConnector object at 0x12579e860>
2023-04-29 03:59:58,431 - asyncio - ERROR - Unclosed client session
client_session: <aiohttp.client.ClientSession object at 0x125b80970>
2023-04-29 03:59:58,432 - asyncio - ERROR - Unclosed connector
connections: ['[(<aiohttp.client_proto.ResponseHandler object at 0x125b7d5a0>, 886579.389120875)]']
connector: <aiohttp.connector.TCPConnector object at 0x12579fb50>
2023-04-29 04:00:00,371 - asyncio - ERROR - Unclosed client session
client_session: <aiohttp.client.ClientSession object at 0x125d40b80>
2023-04-29 04:00:00,371 - asyncio - ERROR - Unclosed connector
connections: ['[(<aiohttp.client_proto.ResponseHandler object at 0x125b7e0e0>, 886581.33077)]']
connector: <aiohttp.connector.TCPConnector object at 0x125d41600>
2023-04-29 04:00:05,616 - asyncio - ERROR - Unclosed client session
client_session: <aiohttp.client.ClientSession object at 0x125da5480>
2023-04-29 04:00:05,616 - asyncio - ERROR - Unclosed connector
connections: ['[(<aiohttp.client_proto.ResponseHandler object at 0x125b7ec80>, 886586.574734291)]']
connector: <aiohttp.connector.TCPConnector object at 0x125d41e70>
2023-04-29 04:01:15,145 - matplotlib.category - INFO - Using categorical units to plot a list of strings that are all parsable as floats or dates. If these strings should be plotted as numbers, cast to the appropriate data type before plotting.
2023-04-29 04:01:15,145 - matplotlib.category - INFO - Using categorical units to plot a list of strings that are all parsable as floats or dates. If these strings should be plotted as numbers, cast to the appropriate data type before plotting.
2023-04-29 04:01:15,147 - matplotlib.category - INFO - Using categorical units to plot a list of strings that are all parsable as floats or dates. If these strings should be plotted as numbers, cast to the appropriate data type before plotting.
