2023-04-29 03:21:52,799 - telegram.ext._application - INFO - Application started
2023-04-29 03:22:28,055 - telegram.ext._application - INFO - Application is stopping. This might take a moment.
2023-04-29 03:22:28,055 - telegram.ext._application - INFO - Application.stop() complete
2023-04-29 03:22:49,931 - telegram.ext._application - INFO - Application started
2023-04-29 03:22:59,823 - telegram.ext._application - ERROR - No error handlers are registered, logging exception.
Traceback (most recent call last):
  File "C:\Users\matve\Desktop\tg_bot_project\venv\lib\site-packages\telegram\ext\_application.py", line 1115, in process_update
    await coroutine
  File "C:\Users\matve\Desktop\tg_bot_project\venv\lib\site-packages\telegram\ext\_conversationhandler.py", line 826, in handle_update
    new_state: object = await handler.handle_update(
  File "C:\Users\matve\Desktop\tg_bot_project\venv\lib\site-packages\telegram\ext\_handler.py", line 141, in handle_update
    return await self.callback(update, context)
  File "C:\Users\matve\Desktop\tg_bot_project\output\app.py", line 475, in change_date
    text, for_robot = await get_weather(self.response, self.name_from, date=int(num) - 3)
  File "C:\Users\matve\Desktop\tg_bot_project\output\funcs_backend.py", line 251, in get_weather
    text += f"Ощущаемая температура °C: \U0001f321{now['feels_like']}\n"
KeyError: 'feels_like'
2023-04-29 03:23:02,128 - telegram.ext._application - ERROR - No error handlers are registered, logging exception.
Traceback (most recent call last):
  File "C:\Users\matve\Desktop\tg_bot_project\venv\lib\site-packages\telegram\ext\_application.py", line 1115, in process_update
    await coroutine
  File "C:\Users\matve\Desktop\tg_bot_project\venv\lib\site-packages\telegram\ext\_conversationhandler.py", line 826, in handle_update
    new_state: object = await handler.handle_update(
  File "C:\Users\matve\Desktop\tg_bot_project\venv\lib\site-packages\telegram\ext\_handler.py", line 141, in handle_update
    return await self.callback(update, context)
  File "C:\Users\matve\Desktop\tg_bot_project\output\app.py", line 475, in change_date
    text, for_robot = await get_weather(self.response, self.name_from, date=int(num) - 3)
  File "C:\Users\matve\Desktop\tg_bot_project\output\funcs_backend.py", line 251, in get_weather
    text += f"Ощущаемая температура °C: \U0001f321{now['feels_like']}\n"
KeyError: 'feels_like'
2023-04-29 03:23:49,442 - telegram.ext._application - ERROR - No error handlers are registered, logging exception.
Traceback (most recent call last):
  File "C:\Users\matve\Desktop\tg_bot_project\venv\lib\site-packages\telegram\ext\_application.py", line 1115, in process_update
    await coroutine
  File "C:\Users\matve\Desktop\tg_bot_project\venv\lib\site-packages\telegram\ext\_conversationhandler.py", line 826, in handle_update
    new_state: object = await handler.handle_update(
  File "C:\Users\matve\Desktop\tg_bot_project\venv\lib\site-packages\telegram\ext\_handler.py", line 141, in handle_update
    return await self.callback(update, context)
  File "C:\Users\matve\Desktop\tg_bot_project\output\app.py", line 475, in change_date
    text, for_robot = await get_weather(self.response, self.name_from, date=int(num) - 3)
  File "C:\Users\matve\Desktop\tg_bot_project\output\funcs_backend.py", line 251, in get_weather
    text += f"Ощущаемая температура °C: \U0001f321{now['feels_like']}\n"
KeyError: 'feels_like'
2023-04-29 03:23:52,832 - telegram.ext._application - ERROR - No error handlers are registered, logging exception.
Traceback (most recent call last):
  File "C:\Users\matve\Desktop\tg_bot_project\venv\lib\site-packages\telegram\ext\_application.py", line 1115, in process_update
    await coroutine
  File "C:\Users\matve\Desktop\tg_bot_project\venv\lib\site-packages\telegram\ext\_conversationhandler.py", line 826, in handle_update
    new_state: object = await handler.handle_update(
  File "C:\Users\matve\Desktop\tg_bot_project\venv\lib\site-packages\telegram\ext\_handler.py", line 141, in handle_update
    return await self.callback(update, context)
  File "C:\Users\matve\Desktop\tg_bot_project\output\app.py", line 475, in change_date
    text, for_robot = await get_weather(self.response, self.name_from, date=int(num) - 3)
  File "C:\Users\matve\Desktop\tg_bot_project\output\funcs_backend.py", line 251, in get_weather
    text += f"Ощущаемая температура °C: \U0001f321{now['feels_like']}\n"
KeyError: 'feels_like'
2023-04-29 03:23:53,673 - telegram.ext._application - ERROR - No error handlers are registered, logging exception.
Traceback (most recent call last):
  File "C:\Users\matve\Desktop\tg_bot_project\venv\lib\site-packages\telegram\ext\_application.py", line 1115, in process_update
    await coroutine
  File "C:\Users\matve\Desktop\tg_bot_project\venv\lib\site-packages\telegram\ext\_conversationhandler.py", line 826, in handle_update
    new_state: object = await handler.handle_update(
  File "C:\Users\matve\Desktop\tg_bot_project\venv\lib\site-packages\telegram\ext\_handler.py", line 141, in handle_update
    return await self.callback(update, context)
  File "C:\Users\matve\Desktop\tg_bot_project\output\app.py", line 475, in change_date
    text, for_robot = await get_weather(self.response, self.name_from, date=int(num) - 3)
  File "C:\Users\matve\Desktop\tg_bot_project\output\funcs_backend.py", line 251, in get_weather
    text += f"Ощущаемая температура °C: \U0001f321{now['feels_like']}\n"
KeyError: 'feels_like'
2023-04-29 03:23:54,454 - telegram.ext._application - ERROR - No error handlers are registered, logging exception.
Traceback (most recent call last):
  File "C:\Users\matve\Desktop\tg_bot_project\venv\lib\site-packages\telegram\ext\_application.py", line 1115, in process_update
    await coroutine
  File "C:\Users\matve\Desktop\tg_bot_project\venv\lib\site-packages\telegram\ext\_conversationhandler.py", line 826, in handle_update
    new_state: object = await handler.handle_update(
  File "C:\Users\matve\Desktop\tg_bot_project\venv\lib\site-packages\telegram\ext\_handler.py", line 141, in handle_update
    return await self.callback(update, context)
  File "C:\Users\matve\Desktop\tg_bot_project\output\app.py", line 475, in change_date
    text, for_robot = await get_weather(self.response, self.name_from, date=int(num) - 3)
  File "C:\Users\matve\Desktop\tg_bot_project\output\funcs_backend.py", line 251, in get_weather
    text += f"Ощущаемая температура °C: \U0001f321{now['feels_like']}\n"
KeyError: 'feels_like'
2023-04-29 03:23:55,054 - telegram.ext._application - ERROR - No error handlers are registered, logging exception.
Traceback (most recent call last):
  File "C:\Users\matve\Desktop\tg_bot_project\venv\lib\site-packages\telegram\ext\_application.py", line 1115, in process_update
    await coroutine
  File "C:\Users\matve\Desktop\tg_bot_project\venv\lib\site-packages\telegram\ext\_conversationhandler.py", line 826, in handle_update
    new_state: object = await handler.handle_update(
  File "C:\Users\matve\Desktop\tg_bot_project\venv\lib\site-packages\telegram\ext\_handler.py", line 141, in handle_update
    return await self.callback(update, context)
  File "C:\Users\matve\Desktop\tg_bot_project\output\app.py", line 475, in change_date
    text, for_robot = await get_weather(self.response, self.name_from, date=int(num) - 3)
  File "C:\Users\matve\Desktop\tg_bot_project\output\funcs_backend.py", line 251, in get_weather
    text += f"Ощущаемая температура °C: \U0001f321{now['feels_like']}\n"
KeyError: 'feels_like'
2023-04-29 03:23:55,479 - telegram.ext._application - ERROR - No error handlers are registered, logging exception.
Traceback (most recent call last):
  File "C:\Users\matve\Desktop\tg_bot_project\venv\lib\site-packages\telegram\ext\_application.py", line 1115, in process_update
    await coroutine
  File "C:\Users\matve\Desktop\tg_bot_project\venv\lib\site-packages\telegram\ext\_conversationhandler.py", line 826, in handle_update
    new_state: object = await handler.handle_update(
  File "C:\Users\matve\Desktop\tg_bot_project\venv\lib\site-packages\telegram\ext\_handler.py", line 141, in handle_update
    return await self.callback(update, context)
  File "C:\Users\matve\Desktop\tg_bot_project\output\app.py", line 475, in change_date
    text, for_robot = await get_weather(self.response, self.name_from, date=int(num) - 3)
  File "C:\Users\matve\Desktop\tg_bot_project\output\funcs_backend.py", line 251, in get_weather
    text += f"Ощущаемая температура °C: \U0001f321{now['feels_like']}\n"
KeyError: 'feels_like'
2023-04-29 03:24:17,568 - telegram.ext._application - INFO - Application is stopping. This might take a moment.
2023-04-29 03:24:17,569 - telegram.ext._application - INFO - Application.stop() complete
2023-04-29 03:24:22,312 - telegram.ext._application - INFO - Application started
2023-04-29 03:24:42,273 - telegram.ext._application - ERROR - No error handlers are registered, logging exception.
Traceback (most recent call last):
  File "C:\Users\matve\Desktop\tg_bot_project\venv\lib\site-packages\telegram\ext\_application.py", line 1115, in process_update
    await coroutine
  File "C:\Users\matve\Desktop\tg_bot_project\venv\lib\site-packages\telegram\ext\_conversationhandler.py", line 826, in handle_update
    new_state: object = await handler.handle_update(
  File "C:\Users\matve\Desktop\tg_bot_project\venv\lib\site-packages\telegram\ext\_handler.py", line 141, in handle_update
    return await self.callback(update, context)
  File "C:\Users\matve\Desktop\tg_bot_project\output\app.py", line 475, in change_date
    text, for_robot = await get_weather(self.response, self.name_from, date=int(num) - 3)
  File "C:\Users\matve\Desktop\tg_bot_project\output\funcs_backend.py", line 250, in get_weather
    now = response["forecasts"][date]["day"]
KeyError: 'day'
2023-04-29 03:24:44,082 - telegram.ext._application - ERROR - No error handlers are registered, logging exception.
Traceback (most recent call last):
  File "C:\Users\matve\Desktop\tg_bot_project\venv\lib\site-packages\telegram\ext\_application.py", line 1115, in process_update
    await coroutine
  File "C:\Users\matve\Desktop\tg_bot_project\venv\lib\site-packages\telegram\ext\_conversationhandler.py", line 826, in handle_update
    new_state: object = await handler.handle_update(
  File "C:\Users\matve\Desktop\tg_bot_project\venv\lib\site-packages\telegram\ext\_handler.py", line 141, in handle_update
    return await self.callback(update, context)
  File "C:\Users\matve\Desktop\tg_bot_project\output\app.py", line 475, in change_date
    text, for_robot = await get_weather(self.response, self.name_from, date=int(num) - 3)
  File "C:\Users\matve\Desktop\tg_bot_project\output\funcs_backend.py", line 250, in get_weather
    now = response["forecasts"][date]["day"]
KeyError: 'day'
2023-04-29 03:25:22,197 - telegram.ext._application - INFO - Application is stopping. This might take a moment.
2023-04-29 03:25:22,198 - telegram.ext._application - INFO - Application.stop() complete
2023-04-29 03:25:26,977 - telegram.ext._application - INFO - Application started
2023-04-29 03:25:36,676 - telegram.ext._application - ERROR - No error handlers are registered, logging exception.
Traceback (most recent call last):
  File "C:\Users\matve\Desktop\tg_bot_project\venv\lib\site-packages\telegram\ext\_application.py", line 1115, in process_update
    await coroutine
  File "C:\Users\matve\Desktop\tg_bot_project\venv\lib\site-packages\telegram\ext\_conversationhandler.py", line 826, in handle_update
    new_state: object = await handler.handle_update(
  File "C:\Users\matve\Desktop\tg_bot_project\venv\lib\site-packages\telegram\ext\_handler.py", line 141, in handle_update
    return await self.callback(update, context)
  File "C:\Users\matve\Desktop\tg_bot_project\output\app.py", line 475, in change_date
    text, for_robot = await get_weather(self.response, self.name_from, date=int(num) - 3)
  File "C:\Users\matve\Desktop\tg_bot_project\output\funcs_backend.py", line 250, in get_weather
    now = response["forecasts"][0]["day"]
KeyError: 'day'
2023-04-29 03:25:41,292 - telegram.ext._application - ERROR - No error handlers are registered, logging exception.
Traceback (most recent call last):
  File "C:\Users\matve\Desktop\tg_bot_project\venv\lib\site-packages\telegram\ext\_application.py", line 1115, in process_update
    await coroutine
  File "C:\Users\matve\Desktop\tg_bot_project\venv\lib\site-packages\telegram\ext\_conversationhandler.py", line 826, in handle_update
    new_state: object = await handler.handle_update(
  File "C:\Users\matve\Desktop\tg_bot_project\venv\lib\site-packages\telegram\ext\_handler.py", line 141, in handle_update
    return await self.callback(update, context)
  File "C:\Users\matve\Desktop\tg_bot_project\output\app.py", line 475, in change_date
    text, for_robot = await get_weather(self.response, self.name_from, date=int(num) - 3)
  File "C:\Users\matve\Desktop\tg_bot_project\output\funcs_backend.py", line 250, in get_weather
    now = response["forecasts"][0]["day"]
KeyError: 'day'
2023-04-29 03:25:42,852 - telegram.ext._application - ERROR - No error handlers are registered, logging exception.
Traceback (most recent call last):
  File "C:\Users\matve\Desktop\tg_bot_project\venv\lib\site-packages\telegram\ext\_application.py", line 1115, in process_update
    await coroutine
  File "C:\Users\matve\Desktop\tg_bot_project\venv\lib\site-packages\telegram\ext\_conversationhandler.py", line 826, in handle_update
    new_state: object = await handler.handle_update(
  File "C:\Users\matve\Desktop\tg_bot_project\venv\lib\site-packages\telegram\ext\_handler.py", line 141, in handle_update
    return await self.callback(update, context)
  File "C:\Users\matve\Desktop\tg_bot_project\output\app.py", line 475, in change_date
    text, for_robot = await get_weather(self.response, self.name_from, date=int(num) - 3)
  File "C:\Users\matve\Desktop\tg_bot_project\output\funcs_backend.py", line 250, in get_weather
    now = response["forecasts"][0]["day"]
KeyError: 'day'
2023-04-29 03:27:08,546 - telegram.ext._application - INFO - Application is stopping. This might take a moment.
2023-04-29 03:27:08,547 - telegram.ext._application - INFO - Application.stop() complete
2023-04-29 03:27:12,742 - telegram.ext._application - INFO - Application started
2023-04-29 03:28:13,620 - asyncio - ERROR - Unclosed client session
client_session: <aiohttp.client.ClientSession object at 0x000001FFCEBA87C0>
2023-04-29 03:28:13,620 - asyncio - ERROR - Unclosed connector
connections: ['[(<aiohttp.client_proto.ResponseHandler object at 0x000001FFCEAEE340>, 1261332.531)]']
connector: <aiohttp.connector.TCPConnector object at 0x000001FFCEBA8A00>
2023-04-29 03:28:41,674 - asyncio - ERROR - Unclosed client session
client_session: <aiohttp.client.ClientSession object at 0x000001FFCECC0DC0>
2023-04-29 03:28:41,674 - asyncio - ERROR - Unclosed connector
connections: ['[(<aiohttp.client_proto.ResponseHandler object at 0x000001FFCECC2400>, 1261360.656)]']
connector: <aiohttp.connector.TCPConnector object at 0x000001FFCECA8A90>
2023-04-29 03:28:48,868 - asyncio - ERROR - Unclosed client session
client_session: <aiohttp.client.ClientSession object at 0x000001FFCEDC5430>
2023-04-29 03:28:48,868 - asyncio - ERROR - Unclosed connector
connections: ['[(<aiohttp.client_proto.ResponseHandler object at 0x000001FFCECC2E20>, 1261367.843)]']
connector: <aiohttp.connector.TCPConnector object at 0x000001FFCECC10D0>
2023-04-29 03:28:52,563 - asyncio - ERROR - Unclosed client session
client_session: <aiohttp.client.ClientSession object at 0x000001FFCED56940>
2023-04-29 03:28:52,564 - asyncio - ERROR - Unclosed connector
connections: ['[(<aiohttp.client_proto.ResponseHandler object at 0x000001FFCEBAB5E0>, 1261371.531)]']
connector: <aiohttp.connector.TCPConnector object at 0x000001FFCECC00D0>
2023-04-29 03:31:49,168 - telegram.ext._application - INFO - Application is stopping. This might take a moment.
2023-04-29 03:31:49,169 - telegram.ext._application - INFO - Application.stop() complete
2023-04-29 03:58:09,482 - asyncio - ERROR - Unclosed client session
client_session: <aiohttp.client.ClientSession object at 0x11ff31ba0>
2023-04-29 03:58:14,531 - telegram.ext._application - INFO - Application started
2023-04-29 03:58:53,668 - telegram.ext._application - INFO - Application is stopping. This might take a moment.
2023-04-29 03:58:53,668 - telegram.ext._application - INFO - Application.stop() complete
2023-04-29 03:58:53,741 - asyncio - ERROR - Unclosed client session
client_session: <aiohttp.client.ClientSession object at 0x12756f7f0>
2023-04-29 03:58:54,943 - telegram.ext._application - INFO - Application started
2023-04-29 03:59:36,828 - asyncio - ERROR - Unclosed client session
client_session: <aiohttp.client.ClientSession object at 0x125a18190>
2023-04-29 03:59:36,830 - asyncio - ERROR - Unclosed connector
connections: ['[(<aiohttp.client_proto.ResponseHandler object at 0x125a0b520>, 886557.786815666)]']
connector: <aiohttp.connector.TCPConnector object at 0x12579ea40>
2023-04-29 03:59:42,681 - asyncio - ERROR - Unclosed client session
client_session: <aiohttp.client.ClientSession object at 0x1258053f0>
2023-04-29 03:59:42,682 - asyncio - ERROR - Unclosed connector
connections: ['[(<aiohttp.client_proto.ResponseHandler object at 0x12576dd20>, 886563.640229791)]']
connector: <aiohttp.connector.TCPConnector object at 0x12579e860>
2023-04-29 03:59:58,431 - asyncio - ERROR - Unclosed client session
client_session: <aiohttp.client.ClientSession object at 0x125b80970>
2023-04-29 03:59:58,432 - asyncio - ERROR - Unclosed connector
connections: ['[(<aiohttp.client_proto.ResponseHandler object at 0x125b7d5a0>, 886579.389120875)]']
connector: <aiohttp.connector.TCPConnector object at 0x12579fb50>
2023-04-29 04:00:00,371 - asyncio - ERROR - Unclosed client session
client_session: <aiohttp.client.ClientSession object at 0x125d40b80>
2023-04-29 04:00:00,371 - asyncio - ERROR - Unclosed connector
connections: ['[(<aiohttp.client_proto.ResponseHandler object at 0x125b7e0e0>, 886581.33077)]']
connector: <aiohttp.connector.TCPConnector object at 0x125d41600>
2023-04-29 04:00:05,616 - asyncio - ERROR - Unclosed client session
client_session: <aiohttp.client.ClientSession object at 0x125da5480>
2023-04-29 04:00:05,616 - asyncio - ERROR - Unclosed connector
connections: ['[(<aiohttp.client_proto.ResponseHandler object at 0x125b7ec80>, 886586.574734291)]']
connector: <aiohttp.connector.TCPConnector object at 0x125d41e70>
2023-04-29 04:01:15,145 - matplotlib.category - INFO - Using categorical units to plot a list of strings that are all parsable as floats or dates. If these strings should be plotted as numbers, cast to the appropriate data type before plotting.
2023-04-29 04:01:15,145 - matplotlib.category - INFO - Using categorical units to plot a list of strings that are all parsable as floats or dates. If these strings should be plotted as numbers, cast to the appropriate data type before plotting.
2023-04-29 04:01:15,147 - matplotlib.category - INFO - Using categorical units to plot a list of strings that are all parsable as floats or dates. If these strings should be plotted as numbers, cast to the appropriate data type before plotting.
2023-04-29 04:04:00,286 - telegram.ext._application - INFO - Application is stopping. This might take a moment.
2023-04-29 04:04:00,287 - telegram.ext._application - INFO - Application.stop() complete
2023-04-29 04:04:00,363 - asyncio - ERROR - Unclosed client session
client_session: <aiohttp.client.ClientSession object at 0x12516fa60>
2023-04-29 16:45:32,353 - telegram.ext._application - INFO - Application started
2023-04-29 16:45:58,179 - telegram.ext._application - INFO - Application is stopping. This might take a moment.
2023-04-29 16:45:58,180 - telegram.ext._application - INFO - Application.stop() complete
2023-04-29 16:45:58,251 - asyncio - ERROR - Unclosed client session
client_session: <aiohttp.client.ClientSession object at 0x12eb898d0>
2023-04-29 16:54:44,109 - telegram.ext._application - INFO - Application started
2023-04-29 16:54:57,950 - telegram.ext._application - ERROR - No error handlers are registered, logging exception.
Traceback (most recent call last):
  File "/Users/nikita/PycharmProjects/tg_bot_project/venv/lib/python3.10/site-packages/telegram/request/_baserequest.py", line 274, in _request_wrapper
    code, payload = await self.do_request(
  File "/Users/nikita/PycharmProjects/tg_bot_project/venv/lib/python3.10/site-packages/telegram/request/_httpxrequest.py", line 213, in do_request
    data = request_data.json_parameters if request_data else None
  File "/Users/nikita/PycharmProjects/tg_bot_project/venv/lib/python3.10/site-packages/telegram/request/_requestdata.py", line 73, in json_parameters
    return {
  File "/Users/nikita/PycharmProjects/tg_bot_project/venv/lib/python3.10/site-packages/telegram/request/_requestdata.py", line 76, in <dictcomp>
    if param.json_value is not None
  File "/Users/nikita/PycharmProjects/tg_bot_project/venv/lib/python3.10/site-packages/telegram/request/_requestparameter.py", line 75, in json_value
    return json.dumps(self.value)
  File "/Library/Frameworks/Python.framework/Versions/3.10/lib/python3.10/json/__init__.py", line 231, in dumps
    return _default_encoder.encode(obj)
  File "/Library/Frameworks/Python.framework/Versions/3.10/lib/python3.10/json/encoder.py", line 199, in encode
    chunks = self.iterencode(o, _one_shot=True)
  File "/Library/Frameworks/Python.framework/Versions/3.10/lib/python3.10/json/encoder.py", line 257, in iterencode
    return _iterencode(o, 0)
  File "/Library/Frameworks/Python.framework/Versions/3.10/lib/python3.10/json/encoder.py", line 179, in default
    raise TypeError(f'Object of type {o.__class__.__name__} '
TypeError: Object of type coroutine is not JSON serializable

The above exception was the direct cause of the following exception:

Traceback (most recent call last):
  File "/Users/nikita/PycharmProjects/tg_bot_project/venv/lib/python3.10/site-packages/telegram/ext/_application.py", line 1115, in process_update
    await coroutine
  File "/Users/nikita/PycharmProjects/tg_bot_project/venv/lib/python3.10/site-packages/telegram/ext/_conversationhandler.py", line 826, in handle_update
    new_state: object = await handler.handle_update(
  File "/Users/nikita/PycharmProjects/tg_bot_project/venv/lib/python3.10/site-packages/telegram/ext/_handler.py", line 141, in handle_update
    return await self.callback(update, context)
  File "/Users/nikita/PycharmProjects/tg_bot_project/tg_bot_project/output/app.py", line 462, in weather_start
    await update.message.reply_text('РџСЂРёРІРµС‚. Р§С‚РѕР±С‹ СѓР·РЅР°С‚СЊ РёРЅС„РѕСЂРјР°С†РёСЋ Рѕ РїРѕРіРѕРґРµ, РІС‹Р±РµСЂРё, РєР°Рє С‚С‹ РїСЂРёС€Р»РµС€СЊ'
  File "/Users/nikita/PycharmProjects/tg_bot_project/venv/lib/python3.10/site-packages/telegram/_message.py", line 1041, in reply_text
    return await self.get_bot().send_message(
  File "/Users/nikita/PycharmProjects/tg_bot_project/venv/lib/python3.10/site-packages/telegram/ext/_extbot.py", line 2618, in send_message
    return await super().send_message(
  File "/Users/nikita/PycharmProjects/tg_bot_project/venv/lib/python3.10/site-packages/telegram/_bot.py", line 368, in decorator
    result = await func(*args, **kwargs)  # skipcq: PYL-E1102
  File "/Users/nikita/PycharmProjects/tg_bot_project/venv/lib/python3.10/site-packages/telegram/_bot.py", line 797, in send_message
    return await self._send_message(
  File "/Users/nikita/PycharmProjects/tg_bot_project/venv/lib/python3.10/site-packages/telegram/ext/_extbot.py", line 494, in _send_message
    result = await super()._send_message(
  File "/Users/nikita/PycharmProjects/tg_bot_project/venv/lib/python3.10/site-packages/telegram/_bot.py", line 549, in _send_message
    result = await self._post(
  File "/Users/nikita/PycharmProjects/tg_bot_project/venv/lib/python3.10/site-packages/telegram/_bot.py", line 456, in _post
    return await self._do_post(
  File "/Users/nikita/PycharmProjects/tg_bot_project/venv/lib/python3.10/site-packages/telegram/ext/_extbot.py", line 312, in _do_post
    return await super()._do_post(
  File "/Users/nikita/PycharmProjects/tg_bot_project/venv/lib/python3.10/site-packages/telegram/_bot.py", line 487, in _do_post
    return await request.post(
  File "/Users/nikita/PycharmProjects/tg_bot_project/venv/lib/python3.10/site-packages/telegram/request/_baserequest.py", line 165, in post
    result = await self._request_wrapper(
  File "/Users/nikita/PycharmProjects/tg_bot_project/venv/lib/python3.10/site-packages/telegram/request/_baserequest.py", line 290, in _request_wrapper
    raise NetworkError(f"Unknown error in HTTP implementation: {repr(exc)}") from exc
telegram.error.NetworkError: Unknown error in HTTP implementation: TypeError('Object of type coroutine is not JSON serializable')
2023-04-29 16:56:07,500 - telegram.ext._application - INFO - Application is stopping. This might take a moment.
2023-04-29 16:56:07,501 - telegram.ext._application - INFO - Application.stop() complete
2023-04-29 16:56:07,571 - asyncio - ERROR - Unclosed client session
client_session: <aiohttp.client.ClientSession object at 0x160b82200>
2023-04-29 16:56:08,887 - telegram.ext._application - INFO - Application started
2023-04-29 16:56:11,635 - telegram.ext._application - ERROR - No error handlers are registered, logging exception.
Traceback (most recent call last):
  File "/Users/nikita/PycharmProjects/tg_bot_project/venv/lib/python3.10/site-packages/telegram/request/_baserequest.py", line 274, in _request_wrapper
    code, payload = await self.do_request(
  File "/Users/nikita/PycharmProjects/tg_bot_project/venv/lib/python3.10/site-packages/telegram/request/_httpxrequest.py", line 213, in do_request
    data = request_data.json_parameters if request_data else None
  File "/Users/nikita/PycharmProjects/tg_bot_project/venv/lib/python3.10/site-packages/telegram/request/_requestdata.py", line 73, in json_parameters
    return {
  File "/Users/nikita/PycharmProjects/tg_bot_project/venv/lib/python3.10/site-packages/telegram/request/_requestdata.py", line 76, in <dictcomp>
    if param.json_value is not None
  File "/Users/nikita/PycharmProjects/tg_bot_project/venv/lib/python3.10/site-packages/telegram/request/_requestparameter.py", line 75, in json_value
    return json.dumps(self.value)
  File "/Library/Frameworks/Python.framework/Versions/3.10/lib/python3.10/json/__init__.py", line 231, in dumps
    return _default_encoder.encode(obj)
  File "/Library/Frameworks/Python.framework/Versions/3.10/lib/python3.10/json/encoder.py", line 199, in encode
    chunks = self.iterencode(o, _one_shot=True)
  File "/Library/Frameworks/Python.framework/Versions/3.10/lib/python3.10/json/encoder.py", line 257, in iterencode
    return _iterencode(o, 0)
  File "/Library/Frameworks/Python.framework/Versions/3.10/lib/python3.10/json/encoder.py", line 179, in default
    raise TypeError(f'Object of type {o.__class__.__name__} '
TypeError: Object of type coroutine is not JSON serializable

The above exception was the direct cause of the following exception:

Traceback (most recent call last):
  File "/Users/nikita/PycharmProjects/tg_bot_project/venv/lib/python3.10/site-packages/telegram/ext/_application.py", line 1115, in process_update
    await coroutine
  File "/Users/nikita/PycharmProjects/tg_bot_project/venv/lib/python3.10/site-packages/telegram/ext/_conversationhandler.py", line 826, in handle_update
    new_state: object = await handler.handle_update(
  File "/Users/nikita/PycharmProjects/tg_bot_project/venv/lib/python3.10/site-packages/telegram/ext/_handler.py", line 141, in handle_update
    return await self.callback(update, context)
  File "/Users/nikita/PycharmProjects/tg_bot_project/tg_bot_project/output/app.py", line 462, in weather_start
    await update.message.reply_text('РџСЂРёРІРµС‚. Р§С‚РѕР±С‹ СѓР·РЅР°С‚СЊ РёРЅС„РѕСЂРјР°С†РёСЋ Рѕ РїРѕРіРѕРґРµ, РІС‹Р±РµСЂРё, РєР°Рє С‚С‹ РїСЂРёС€Р»РµС€СЊ'
  File "/Users/nikita/PycharmProjects/tg_bot_project/venv/lib/python3.10/site-packages/telegram/_message.py", line 1041, in reply_text
    return await self.get_bot().send_message(
  File "/Users/nikita/PycharmProjects/tg_bot_project/venv/lib/python3.10/site-packages/telegram/ext/_extbot.py", line 2618, in send_message
    return await super().send_message(
  File "/Users/nikita/PycharmProjects/tg_bot_project/venv/lib/python3.10/site-packages/telegram/_bot.py", line 368, in decorator
    result = await func(*args, **kwargs)  # skipcq: PYL-E1102
  File "/Users/nikita/PycharmProjects/tg_bot_project/venv/lib/python3.10/site-packages/telegram/_bot.py", line 797, in send_message
    return await self._send_message(
  File "/Users/nikita/PycharmProjects/tg_bot_project/venv/lib/python3.10/site-packages/telegram/ext/_extbot.py", line 494, in _send_message
    result = await super()._send_message(
  File "/Users/nikita/PycharmProjects/tg_bot_project/venv/lib/python3.10/site-packages/telegram/_bot.py", line 549, in _send_message
    result = await self._post(
  File "/Users/nikita/PycharmProjects/tg_bot_project/venv/lib/python3.10/site-packages/telegram/_bot.py", line 456, in _post
    return await self._do_post(
  File "/Users/nikita/PycharmProjects/tg_bot_project/venv/lib/python3.10/site-packages/telegram/ext/_extbot.py", line 312, in _do_post
    return await super()._do_post(
  File "/Users/nikita/PycharmProjects/tg_bot_project/venv/lib/python3.10/site-packages/telegram/_bot.py", line 487, in _do_post
    return await request.post(
  File "/Users/nikita/PycharmProjects/tg_bot_project/venv/lib/python3.10/site-packages/telegram/request/_baserequest.py", line 165, in post
    result = await self._request_wrapper(
  File "/Users/nikita/PycharmProjects/tg_bot_project/venv/lib/python3.10/site-packages/telegram/request/_baserequest.py", line 290, in _request_wrapper
    raise NetworkError(f"Unknown error in HTTP implementation: {repr(exc)}") from exc
telegram.error.NetworkError: Unknown error in HTTP implementation: TypeError('Object of type coroutine is not JSON serializable')
2023-04-29 16:57:38,718 - telegram.ext._application - INFO - Application is stopping. This might take a moment.
2023-04-29 16:57:38,719 - telegram.ext._application - INFO - Application.stop() complete
2023-04-29 16:57:38,789 - asyncio - ERROR - Unclosed client session
client_session: <aiohttp.client.ClientSession object at 0x11e2820b0>
2023-04-29 16:57:39,932 - telegram.ext._application - INFO - Application started
2023-04-29 16:58:13,629 - telegram.ext._application - INFO - Application is stopping. This might take a moment.
2023-04-29 16:58:13,629 - telegram.ext._application - INFO - Application.stop() complete
2023-04-29 16:58:13,699 - asyncio - ERROR - Unclosed client session
client_session: <aiohttp.client.ClientSession object at 0x11fb821a0>
2023-04-29 16:58:16,649 - telegram.ext._application - INFO - Application started
2023-04-29 16:58:47,455 - telegram.ext._application - INFO - Application is stopping. This might take a moment.
2023-04-29 16:58:47,455 - telegram.ext._application - INFO - Application.stop() complete
2023-04-29 16:58:47,534 - asyncio - ERROR - Unclosed client session
client_session: <aiohttp.client.ClientSession object at 0x1311ed780>
2023-04-29 16:58:50,544 - telegram.ext._application - INFO - Application started
2023-04-29 18:31:26,109 - telegram.ext._application - INFO - Application is stopping. This might take a moment.
2023-04-29 18:31:26,112 - telegram.ext._application - INFO - Application.stop() complete
2023-04-29 18:31:26,192 - asyncio - ERROR - Unclosed client session
client_session: <aiohttp.client.ClientSession object at 0x1600863b0>
2023-04-29 18:31:27,666 - telegram.ext._application - INFO - Application started
2023-04-29 18:31:49,523 - telegram.ext._application - ERROR - No error handlers are registered, logging exception.
Traceback (most recent call last):
  File "/Users/nikita/PycharmProjects/tg_bot_project/venv/lib/python3.10/site-packages/telegram/ext/_application.py", line 1115, in process_update
    await coroutine
  File "/Users/nikita/PycharmProjects/tg_bot_project/venv/lib/python3.10/site-packages/telegram/ext/_conversationhandler.py", line 826, in handle_update
    new_state: object = await handler.handle_update(
  File "/Users/nikita/PycharmProjects/tg_bot_project/venv/lib/python3.10/site-packages/telegram/ext/_handler.py", line 141, in handle_update
    return await self.callback(update, context)
  File "/Users/nikita/PycharmProjects/tg_bot_project/tg_bot_project/output/app.py", line 160, in address_loc
    total_msg_func(update)
  File "/Users/nikita/PycharmProjects/tg_bot_project/tg_bot_project/output/funcs_backend.py", line 354, in total_msg_func
    user.total_len += len("".join(update.message.text.split()))
AttributeError: 'NoneType' object has no attribute 'split'
2023-04-29 18:31:57,459 - telegram.ext._application - ERROR - No error handlers are registered, logging exception.
Traceback (most recent call last):
  File "/Users/nikita/PycharmProjects/tg_bot_project/venv/lib/python3.10/site-packages/telegram/ext/_application.py", line 1115, in process_update
    await coroutine
  File "/Users/nikita/PycharmProjects/tg_bot_project/venv/lib/python3.10/site-packages/telegram/ext/_conversationhandler.py", line 826, in handle_update
    new_state: object = await handler.handle_update(
  File "/Users/nikita/PycharmProjects/tg_bot_project/venv/lib/python3.10/site-packages/telegram/ext/_handler.py", line 141, in handle_update
    return await self.callback(update, context)
  File "/Users/nikita/PycharmProjects/tg_bot_project/tg_bot_project/output/app.py", line 160, in address_loc
    total_msg_func(update)
  File "/Users/nikita/PycharmProjects/tg_bot_project/tg_bot_project/output/funcs_backend.py", line 354, in total_msg_func
    user.total_len += len("".join(update.message.text.split()))
AttributeError: 'NoneType' object has no attribute 'split'
2023-04-29 18:44:28,953 - telegram.ext._application - INFO - Application is stopping. This might take a moment.
2023-04-29 18:44:28,953 - telegram.ext._application - INFO - Application.stop() complete
2023-04-29 18:44:29,034 - asyncio - ERROR - Unclosed client session
client_session: <aiohttp.client.ClientSession object at 0x129910c70>
2023-04-29 18:44:30,411 - telegram.ext._application - INFO - Application started
2023-04-29 18:45:10,603 - telegram.ext._application - ERROR - No error handlers are registered, logging exception.
Traceback (most recent call last):
  File "/Users/nikita/PycharmProjects/tg_bot_project/venv/lib/python3.10/site-packages/telegram/ext/_application.py", line 1115, in process_update
    await coroutine
  File "/Users/nikita/PycharmProjects/tg_bot_project/venv/lib/python3.10/site-packages/telegram/ext/_conversationhandler.py", line 826, in handle_update
    new_state: object = await handler.handle_update(
  File "/Users/nikita/PycharmProjects/tg_bot_project/venv/lib/python3.10/site-packages/telegram/ext/_handler.py", line 141, in handle_update
    return await self.callback(update, context)
  File "/Users/nikita/PycharmProjects/tg_bot_project/tg_bot_project/output/app.py", line 277, in start_game
    await update.message.reply_text(f'Р”Р»СЏ РЅР°С‡Р°Р»Р° РІС‹Р№РґРё РёР· РїСЂРµРґС‹РґСѓС‰РµРіРѕ РґРёР°Р»РѕРіР°: {context.user_data["cmd"]}')
KeyError: 'cmd'
2023-04-29 18:45:17,159 - telegram.ext._application - ERROR - No error handlers are registered, logging exception.
Traceback (most recent call last):
  File "/Users/nikita/PycharmProjects/tg_bot_project/venv/lib/python3.10/site-packages/telegram/ext/_application.py", line 1115, in process_update
    await coroutine
  File "/Users/nikita/PycharmProjects/tg_bot_project/venv/lib/python3.10/site-packages/telegram/ext/_conversationhandler.py", line 826, in handle_update
    new_state: object = await handler.handle_update(
  File "/Users/nikita/PycharmProjects/tg_bot_project/venv/lib/python3.10/site-packages/telegram/ext/_handler.py", line 141, in handle_update
    return await self.callback(update, context)
  File "/Users/nikita/PycharmProjects/tg_bot_project/tg_bot_project/output/app.py", line 277, in start_game
    await update.message.reply_text(f'Р”Р»СЏ РЅР°С‡Р°Р»Р° РІС‹Р№РґРё РёР· РїСЂРµРґС‹РґСѓС‰РµРіРѕ РґРёР°Р»РѕРіР°: {context.user_data["cmd"]}')
KeyError: 'cmd'
2023-04-29 18:46:09,026 - telegram.ext._application - INFO - Application is stopping. This might take a moment.
2023-04-29 18:46:09,026 - telegram.ext._application - INFO - Application.stop() complete
2023-04-29 18:46:09,096 - asyncio - ERROR - Unclosed client session
client_session: <aiohttp.client.ClientSession object at 0x11db82920>
2023-04-29 18:46:10,253 - telegram.ext._application - INFO - Application started
2023-04-29 18:56:23,164 - matplotlib.category - INFO - Using categorical units to plot a list of strings that are all parsable as floats or dates. If these strings should be plotted as numbers, cast to the appropriate data type before plotting.
2023-04-29 18:56:23,165 - matplotlib.category - INFO - Using categorical units to plot a list of strings that are all parsable as floats or dates. If these strings should be plotted as numbers, cast to the appropriate data type before plotting.
2023-04-29 18:56:23,166 - matplotlib.category - INFO - Using categorical units to plot a list of strings that are all parsable as floats or dates. If these strings should be plotted as numbers, cast to the appropriate data type before plotting.
2023-04-29 19:37:16,152 - telegram.ext._application - INFO - Application is stopping. This might take a moment.
2023-04-29 19:37:16,152 - telegram.ext._application - INFO - Application.stop() complete
2023-04-29 19:37:16,223 - asyncio - ERROR - Unclosed client session
client_session: <aiohttp.client.ClientSession object at 0x12567edd0>
2023-04-29 19:37:17,509 - telegram.ext._application - INFO - Application started
2023-04-29 19:38:01,343 - telegram.ext._application - INFO - Application is stopping. This might take a moment.
2023-04-29 19:38:01,343 - telegram.ext._application - INFO - Application.stop() complete
2023-04-29 19:38:01,412 - asyncio - ERROR - Unclosed client session
client_session: <aiohttp.client.ClientSession object at 0x121c368f0>
2023-04-29 19:38:02,691 - telegram.ext._application - INFO - Application started
